Workbook
Name chBelow: OFFSET(Calc!$H$2,0,0,MAX(1,Calc!$M$4),1)
Name chLab: OFFSET(Calc!$D$2,0,0,MAX(1,Calc!$M$4),1)
Name chMet: OFFSET(Calc!$G$2,0,0,MAX(1,Calc!$M$4),1)
Name chPart: OFFSET(Calc!$I$2,0,0,MAX(1,Calc!$M$4),1)
Name chReq: OFFSET(Calc!$J$2,0,0,MAX(1,Calc!$M$4),1)
Name nHours: Calc!$M$4
Name PicArea: OFFSET(Log!$A$1,0,0,21+Calc!$M$4,14)
Name ReqInit: Log!$P$12

Sheet Log
B2: =IF($P$9="","POURING REPORT",$P$9) -> POURING REPORT | J2: =IF($P$10="","",$P$10)
B3: =IF($P$11="","","Total quantity Q = "&TEXT($P$11,"#,##0")&" m³")
B5: REQUESTED RATE | D5: ACTUAL AVG RATE | G5: LOADED | L5: REJECTED
B6: {=IF(nHours>0,INDEX(Calc!$K$2:$K$49,nHours),ReqInit)} -> 0 | D6: =IF(Calc!$M$3-Calc!$M$1>=30,SUM(Messages!$E:$E)/((Calc!$M$3-Calc!$M$1)/60),"") | G6: =ROUND(SUM(Messages!$E:$E),1) -> 0 | L6: =ROUND(SUM(Messages!$J:$J)+N($P$14),1) -> 0
B7: PROGRESS | G7: REMAINING | L7: EXPECTED FINISH
B8: =IF(N($P$11)<=0,"",_xlfn.LET(_xlpm.p,($G$6-$L$6)/$P$11,_xlpm.n,ROUND(MAX(0,MIN(1,_xlpm.p))*20,0),REPT("■",_xlpm.n)&REPT("□",20-_xlpm.n)&" "&TEXT(_xlpm.p,"0%"))) | G8: =IF($P$11="","",ROUND($P$11-$G$6+$L$6,1)) | L8: =IF(OR($G$8="",NOT(ISNUMBER($D$6))),"—",IF($G$8<=0,"Done",IF($D$6<=0,"—",_xlfn.LET(_xlpm.f,Calc!$M$3+$G$8/$D$6*60,_xlpm.dt,IF(ISNUMBER($P$10),INT($P$10),TODAY())+INT(_xlpm.f/1440)-INT(Calc!$M$1/1440),IF(_xlpm.dt=TODAY(),"Today",IF(_xlpm.dt=TODAY()+1,"Tomorrow",TEXT(_xlpm.dt,"[$-409]ddd d mmm")))&" "&TEXT(MOD(_xlpm.f,1440)/1440,"[$-409]h:mm AM/PM"))))) -> — | O8: POUR SETUP ✎
O9: Title
O10: Date
O11: Total quantity Q (m³)
O12: Requested rate (m³/h)
O13: Start time (optional, auto)
O14: Rejected m³ (manual, optional)
O16: Messages to check ⚠ | P16: =COUNTIF(Messages!$G:$G,"⚠*") -> 0
O17: Trucks loaded | P17: =COUNT(Messages!$K:$K) -> 0
B19: TIME | C19: L1 | D19: L2 | E19: V3 | F19: V4 | G19: V5 | H19: TRUCKS | I19: RATE m³/h | J19: COMMENTS | O19: REQUESTED RATE CHANGE ✎ | P19: type the new rate in the hour it changed | Q19: TRUCKS
A20: =IF(ROW()-19<=nHours,1,IF(nHours=0,0,IF(ROW()-19=nHours+1,2,0))) -> 0 | B20: =IF($A20=1,TEXT((Calc!$C2-60)/1440,"hh:mm")&" – "&TEXT(Calc!$C2/1440,"hh:mm"),IF($A20=2,"TOTAL","")) | C20: =IF($A20=1,_xlfn.LET(_xlpm.s,SUMIFS(Messages!$E:$E,Messages!$D:$D,C$19,Messages!$K:$K,">="&Calc!$B2,Messages!$K:$K,"<"&Calc!$C2),IF(_xlpm.s=0,"",_xlpm.s)),IF($A20=2,SUMIFS(Messages!$E:$E,Messages!$D:$D,C$19),IF($A20=3,IFERROR(TEXT(SUMIFS(Messages!$E:$E,Messages!$D:$D,C$19)/SUM(Messages!$E:$E),"0%"),""),""))) | D20: =IF($A20=1,_xlfn.LET(_xlpm.s,SUMIFS(Messages!$E:$E,Messages!$D:$D,D$19,Messages!$K:$K,">="&Calc!$B2,Messages!$K:$K,"<"&Calc!$C2),IF(_xlpm.s=0,"",_xlpm.s)),IF($A20=2,SUMIFS(Messages!$E:$E,Messages!$D:$D,D$19),IF($A20=3,IFERROR(TEXT(SUMIFS(Messages!$E:$E,Messages!$D:$D,D$19)/SUM(Messages!$E:$E),"0%"),""),""))) | E20: =IF($A20=1,_xlfn.LET(_xlpm.s,SUMIFS(Messages!$E:$E,Messages!$D:$D,E$19,Messages!$K:$K,">="&Calc!$B2,Messages!$K:$K,"<"&Calc!$C2),IF(_xlpm.s=0,"",_xlpm.s)),IF($A20=2,SUMIFS(Messages!$E:$E,Messages!$D:$D,E$19),IF($A20=3,IFERROR(TEXT(SUMIFS(Messages!$E:$E,Messages!$D:$D,E$19)/SUM(Messages!$E:$E),"0%"),""),""))) | F20: =IF($A20=1,_xlfn.LET(_xlpm.s,SUMIFS(Messages!$E:$E,Messages!$D:$D,F$19,Messages!$K:$K,">="&Calc!$B2,Messages!$K:$K,"<"&Calc!$C2),IF(_xlpm.s=0,"",_xlpm.s)),IF($A20=2,SUMIFS(Messages!$E:$E,Messages!$D:$D,F$19),IF($A20=3,IFERROR(TEXT(SUMIFS(Messages!$E:$E,Messages!$D:$D,F$19)/SUM(Messages!$E:$E),"0%"),""),""))) | G20: =IF($A20=1,_xlfn.LET(_xlpm.s,SUMIFS(Messages!$E:$E,Messages!$D:$D,G$19,Messages!$K:$K,">="&Calc!$B2,Messages!$K:$K,"<"&Calc!$C2),IF(_xlpm.s=0,"",_xlpm.s)),IF($A20=2,SUMIFS(Messages!$E:$E,Messages!$D:$D,G$19),IF($A20=3,IFERROR(TEXT(SUMIFS(Messages!$E:$E,Messages!$D:$D,G$19)/SUM(Messages!$E:$E),"0%"),""),""))) | H20: =IF($A20=1,COUNTIFS(Messages!$K:$K,">="&Calc!$B2,Messages!$K:$K,"<"&Calc!$C2),IF($A20=2,COUNT(Messages!$K:$K),"")) | I20: =IF($A20=1,SUMIFS(Messages!$E:$E,Messages!$K:$K,">="&Calc!$B2,Messages!$K:$K,"<"&Calc!$C2),IF($A20=2,SUM(Messages!$E:$E),"")) | J20: =IF(AND($A20=1,$O20<>""),IF($O20<>IF(ROW()=20,ReqInit,Calc!$K1),"Client asked for "&$O20&" m³/h.",""),"") | Q20: =IF($A20>0,$H20,"")
A21: =IF(ROW()-19<=nHours,1,IF(nHours=0,0,IF(ROW()-19=nHours+1,2,0))) -> 0 | B21: =IF($A21=1,TEXT((Calc!$C3-60)/1440,"hh:mm")&" – "&TEXT(Calc!$C3/1440,"hh:mm"),IF($A21=2,"TOTAL","")) | C21: =IF($A21=1,_xlfn.LET(_xlpm.s,SUMIFS(Messages!$E:$E,Messages!$D:$D,C$19,Messages!$K:$K,">="&Calc!$B3,Messages!$K:$K,"<"&Calc!$C3),IF(_xlpm.s=0,"",_xlpm.s)),IF($A21=2,SUMIFS(Messages!$E:$E,Messages!$D:$D,C$19),IF($A21=3,IFERROR(TEXT(SUMIFS(Messages!$E:$E,Messages!$D:$D,C$19)/SUM(Messages!$E:$E),"0%"),""),""))) | D21: =IF($A21=1,_xlfn.LET(_xlpm.s,SUMIFS(Messages!$E:$E,Messages!$D:$D,D$19,Messages!$K:$K,">="&Calc!$B3,Messages!$K:$K,"<"&Calc!$C3),IF(_xlpm.s=0,"",_xlpm.s)),IF($A21=2,SUMIFS(Messages!$E:$E,Messages!$D:$D,D$19),IF($A21=3,IFERROR(TEXT(SUMIFS(Messages!$E:$E,Messages!$D:$D,D$19)/SUM(Messages!$E:$E),"0%"),""),""))) | E21: =IF($A21=1,_xlfn.LET(_xlpm.s,SUMIFS(Messages!$E:$E,Messages!$D:$D,E$19,Messages!$K:$K,">="&Calc!$B3,Messages!$K:$K,"<"&Calc!$C3),IF(_xlpm.s=0,"",_xlpm.s)),IF($A21=2,SUMIFS(Messages!$E:$E,Messages!$D:$D,E$19),IF($A21=3,IFERROR(TEXT(SUMIFS(Messages!$E:$E,Messages!$D:$D,E$19)/SUM(Messages!$E:$E),"0%"),""),""))) | F21: =IF($A21=1,_xlfn.LET(_xlpm.s,SUMIFS(Messages!$E:$E,Messages!$D:$D,F$19,Messages!$K:$K,">="&Calc!$B3,Messages!$K:$K,"<"&Calc!$C3),IF(_xlpm.s=0,"",_xlpm.s)),IF($A21=2,SUMIFS(Messages!$E:$E,Messages!$D:$D,F$19),IF($A21=3,IFERROR(TEXT(SUMIFS(Messages!$E:$E,Messages!$D:$D,F$19)/SUM(Messages!$E:$E),"0%"),""),""))) | G21: =IF($A21=1,_xlfn.LET(_xlpm.s,SUMIFS(Messages!$E:$E,Messages!$D:$D,G$19,Messages!$K:$K,">="&Calc!$B3,Messages!$K:$K,"<"&Calc!$C3),IF(_xlpm.s=0,"",_xlpm.s)),IF($A21=2,SUMIFS(Messages!$E:$E,Messages!$D:$D,G$19),IF($A21=3,IFERROR(TEXT(SUMIFS(Messages!$E:$E,Messages!$D:$D,G$19)/SUM(Messages!$E:$E),"0%"),""),""))) | H21: =IF($A21=1,COUNTIFS(Messages!$K:$K,">="&Calc!$B3,Messages!$K:$K,"<"&Calc!$C3),IF($A21=2,COUNT(Messages!$K:$K),"")) | I21: =IF($A21=1,SUMIFS(Messages!$E:$E,Messages!$K:$K,">="&Calc!$B3,Messages!$K:$K,"<"&Calc!$C3),IF($A21=2,SUM(Messages!$E:$E),"")) | J21: =IF(AND($A21=1,$O21<>""),IF($O21<>IF(ROW()=20,ReqInit,Calc!$K2),"Client asked for "&$O21&" m³/h.",""),"") | Q21: =IF($A21>0,$H21,"")
A22: =IF(ROW()-19<=nHours,1,IF(nHours=0,0,IF(ROW()-19=nHours+1,2,0))) -> 0 | B22: =IF($A22=1,TEXT((Calc!$C4-60)/1440,"hh:mm")&" – "&TEXT(Calc!$C4/1440,"hh:mm"),IF($A22=2,"TOTAL","")) | C22: =IF($A22=1,_xlfn.LET(_xlpm.s,SUMIFS(Messages!$E:$E,Messages!$D:$D,C$19,Messages!$K:$K,">="&Calc!$B4,Messages!$K:$K,"<"&Calc!$C4),IF(_xlpm.s=0,"",_xlpm.s)),IF($A22=2,SUMIFS(Messages!$E:$E,Messages!$D:$D,C$19),IF($A22=3,IFERROR(TEXT(SUMIFS(Messages!$E:$E,Messages!$D:$D,C$19)/SUM(Messages!$E:$E),"0%"),""),""))) | D22: =IF($A22=1,_xlfn.LET(_xlpm.s,SUMIFS(Messages!$E:$E,Messages!$D:$D,D$19,Messages!$K:$K,">="&Calc!$B4,Messages!$K:$K,"<"&Calc!$C4),IF(_xlpm.s=0,"",_xlpm.s)),IF($A22=2,SUMIFS(Messages!$E:$E,Messages!$D:$D,D$19),IF($A22=3,IFERROR(TEXT(SUMIFS(Messages!$E:$E,Messages!$D:$D,D$19)/SUM(Messages!$E:$E),"0%"),""),""))) | E22: =IF($A22=1,_xlfn.LET(_xlpm.s,SUMIFS(Messages!$E:$E,Messages!$D:$D,E$19,Messages!$K:$K,">="&Calc!$B4,Messages!$K:$K,"<"&Calc!$C4),IF(_xlpm.s=0,"",_xlpm.s)),IF($A22=2,SUMIFS(Messages!$E:$E,Messages!$D:$D,E$19),IF($A22=3,IFERROR(TEXT(SUMIFS(Messages!$E:$E,Messages!$D:$D,E$19)/SUM(Messages!$E:$E),"0%"),""),""))) | F22: =IF($A22=1,_xlfn.LET(_xlpm.s,SUMIFS(Messages!$E:$E,Messages!$D:$D,F$19,Messages!$K:$K,">="&Calc!$B4,Messages!$K:$K,"<"&Calc!$C4),IF(_xlpm.s=0,"",_xlpm.s)),IF($A22=2,SUMIFS(Messages!$E:$E,Messages!$D:$D,F$19),IF($A22=3,IFERROR(TEXT(SUMIFS(Messages!$E:$E,Messages!$D:$D,F$19)/SUM(Messages!$E:$E),"0%"),""),""))) | G22: =IF($A22=1,_xlfn.LET(_xlpm.s,SUMIFS(Messages!$E:$E,Messages!$D:$D,G$19,Messages!$K:$K,">="&Calc!$B4,Messages!$K:$K,"<"&Calc!$C4),IF(_xlpm.s=0,"",_xlpm.s)),IF($A22=2,SUMIFS(Messages!$E:$E,Messages!$D:$D,G$19),IF($A22=3,IFERROR(TEXT(SUMIFS(Messages!$E:$E,Messages!$D:$D,G$19)/SUM(Messages!$E:$E),"0%"),""),""))) | H22: =IF($A22=1,COUNTIFS(Messages!$K:$K,">="&Calc!$B4,Messages!$K:$K,"<"&Calc!$C4),IF($A22=2,COUNT(Messages!$K:$K),"")) | I22: =IF($A22=1,SUMIFS(Messages!$E:$E,Messages!$K:$K,">="&Calc!$B4,Messages!$K:$K,"<"&Calc!$C4),IF($A22=2,SUM(Messages!$E:$E),"")) | J22: =IF(AND($A22=1,$O22<>""),IF($O22<>IF(ROW()=20,ReqInit,Calc!$K3),"Client asked for "&$O22&" m³/h.",""),"") | Q22: =IF($A22>0,$H22,"")
A23: =IF(ROW()-19<=nHours,1,IF(nHours=0,0,IF(ROW()-19=nHours+1,2,0))) -> 0 | B23: =IF($A23=1,TEXT((Calc!$C5-60)/1440,"hh:mm")&" – "&TEXT(Calc!$C5/1440,"hh:mm"),IF($A23=2,"TOTAL","")) | C23: =IF($A23=1,_xlfn.LET(_xlpm.s,SUMIFS(Messages!$E:$E,Messages!$D:$D,C$19,Messages!$K:$K,">="&Calc!$B5,Messages!$K:$K,"<"&Calc!$C5),IF(_xlpm.s=0,"",_xlpm.s)),IF($A23=2,SUMIFS(Messages!$E:$E,Messages!$D:$D,C$19),IF($A23=3,IFERROR(TEXT(SUMIFS(Messages!$E:$E,Messages!$D:$D,C$19)/SUM(Messages!$E:$E),"0%"),""),""))) | D23: =IF($A23=1,_xlfn.LET(_xlpm.s,SUMIFS(Messages!$E:$E,Messages!$D:$D,D$19,Messages!$K:$K,">="&Calc!$B5,Messages!$K:$K,"<"&Calc!$C5),IF(_xlpm.s=0,"",_xlpm.s)),IF($A23=2,SUMIFS(Messages!$E:$E,Messages!$D:$D,D$19),IF($A23=3,IFERROR(TEXT(SUMIFS(Messages!$E:$E,Messages!$D:$D,D$19)/SUM(Messages!$E:$E),"0%"),""),""))) | E23: =IF($A23=1,_xlfn.LET(_xlpm.s,SUMIFS(Messages!$E:$E,Messages!$D:$D,E$19,Messages!$K:$K,">="&Calc!$B5,Messages!$K:$K,"<"&Calc!$C5),IF(_xlpm.s=0,"",_xlpm.s)),IF($A23=2,SUMIFS(Messages!$E:$E,Messages!$D:$D,E$19),IF($A23=3,IFERROR(TEXT(SUMIFS(Messages!$E:$E,Messages!$D:$D,E$19)/SUM(Messages!$E:$E),"0%"),""),""))) | F23: =IF($A23=1,_xlfn.LET(_xlpm.s,SUMIFS(Messages!$E:$E,Messages!$D:$D,F$19,Messages!$K:$K,">="&Calc!$B5,Messages!$K:$K,"<"&Calc!$C5),IF(_xlpm.s=0,"",_xlpm.s)),IF($A23=2,SUMIFS(Messages!$E:$E,Messages!$D:$D,F$19),IF($A23=3,IFERROR(TEXT(SUMIFS(Messages!$E:$E,Messages!$D:$D,F$19)/SUM(Messages!$E:$E),"0%"),""),""))) | G23: =IF($A23=1,_xlfn.LET(_xlpm.s,SUMIFS(Messages!$E:$E,Messages!$D:$D,G$19,Messages!$K:$K,">="&Calc!$B5,Messages!$K:$K,"<"&Calc!$C5),IF(_xlpm.s=0,"",_xlpm.s)),IF($A23=2,SUMIFS(Messages!$E:$E,Messages!$D:$D,G$19),IF($A23=3,IFERROR(TEXT(SUMIFS(Messages!$E:$E,Messages!$D:$D,G$19)/SUM(Messages!$E:$E),"0%"),""),""))) | H23: =IF($A23=1,COUNTIFS(Messages!$K:$K,">="&Calc!$B5,Messages!$K:$K,"<"&Calc!$C5),IF($A23=2,COUNT(Messages!$K:$K),"")) | I23: =IF($A23=1,SUMIFS(Messages!$E:$E,Messages!$K:$K,">="&Calc!$B5,Messages!$K:$K,"<"&Calc!$C5),IF($A23=2,SUM(Messages!$E:$E),"")) | J23: =IF(AND($A23=1,$O23<>""),IF($O23<>IF(ROW()=20,ReqInit,Calc!$K4),"Client asked for "&$O23&" m³/h.",""),"") | Q23: =IF($A23>0,$H23,"")
A24: =IF(ROW()-19<=nHours,1,IF(nHours=0,0,IF(ROW()-19=nHours+1,2,0))) -> 0 | B24: =IF($A24=1,TEXT((Calc!$C6-60)/1440,"hh:mm")&" – "&TEXT(Calc!$C6/1440,"hh:mm"),IF($A24=2,"TOTAL","")) | C24: =IF($A24=1,_xlfn.LET(_xlpm.s,SUMIFS(Messages!$E:$E,Messages!$D:$D,C$19,Messages!$K:$K,">="&Calc!$B6,Messages!$K:$K,"<"&Calc!$C6),IF(_xlpm.s=0,"",_xlpm.s)),IF($A24=2,SUMIFS(Messages!$E:$E,Messages!$D:$D,C$19),IF($A24=3,IFERROR(TEXT(SUMIFS(Messages!$E:$E,Messages!$D:$D,C$19)/SUM(Messages!$E:$E),"0%"),""),""))) | D24: =IF($A24=1,_xlfn.LET(_xlpm.s,SUMIFS(Messages!$E:$E,Messages!$D:$D,D$19,Messages!$K:$K,">="&Calc!$B6,Messages!$K:$K,"<"&Calc!$C6),IF(_xlpm.s=0,"",_xlpm.s)),IF($A24=2,SUMIFS(Messages!$E:$E,Messages!$D:$D,D$19),IF($A24=3,IFERROR(TEXT(SUMIFS(Messages!$E:$E,Messages!$D:$D,D$19)/SUM(Messages!$E:$E),"0%"),""),""))) | E24: =IF($A24=1,_xlfn.LET(_xlpm.s,SUMIFS(Messages!$E:$E,Messages!$D:$D,E$19,Messages!$K:$K,">="&Calc!$B6,Messages!$K:$K,"<"&Calc!$C6),IF(_xlpm.s=0,"",_xlpm.s)),IF($A24=2,SUMIFS(Messages!$E:$E,Messages!$D:$D,E$19),IF($A24=3,IFERROR(TEXT(SUMIFS(Messages!$E:$E,Messages!$D:$D,E$19)/SUM(Messages!$E:$E),"0%"),""),""))) | F24: =IF($A24=1,_xlfn.LET(_xlpm.s,SUMIFS(Messages!$E:$E,Messages!$D:$D,F$19,Messages!$K:$K,">="&Calc!$B6,Messages!$K:$K,"<"&Calc!$C6),IF(_xlpm.s=0,"",_xlpm.s)),IF($A24=2,SUMIFS(Messages!$E:$E,Messages!$D:$D,F$19),IF($A24=3,IFERROR(TEXT(SUMIFS(Messages!$E:$E,Messages!$D:$D,F$19)/SUM(Messages!$E:$E),"0%"),""),""))) | G24: =IF($A24=1,_xlfn.LET(_xlpm.s,SUMIFS(Messages!$E:$E,Messages!$D:$D,G$19,Messages!$K:$K,">="&Calc!$B6,Messages!$K:$K,"<"&Calc!$C6),IF(_xlpm.s=0,"",_xlpm.s)),IF($A24=2,SUMIFS(Messages!$E:$E,Messages!$D:$D,G$19),IF($A24=3,IFERROR(TEXT(SUMIFS(Messages!$E:$E,Messages!$D:$D,G$19)/SUM(Messages!$E:$E),"0%"),""),""))) | H24: =IF($A24=1,COUNTIFS(Messages!$K:$K,">="&Calc!$B6,Messages!$K:$K,"<"&Calc!$C6),IF($A24=2,COUNT(Messages!$K:$K),"")) | I24: =IF($A24=1,SUMIFS(Messages!$E:$E,Messages!$K:$K,">="&Calc!$B6,Messages!$K:$K,"<"&Calc!$C6),IF($A24=2,SUM(Messages!$E:$E),"")) | J24: =IF(AND($A24=1,$O24<>""),IF($O24<>IF(ROW()=20,ReqInit,Calc!$K5),"Client asked for "&$O24&" m³/h.",""),"") | Q24: =IF($A24>0,$H24,"")
A25: =IF(ROW()-19<=nHours,1,IF(nHours=0,0,IF(ROW()-19=nHours+1,2,0))) -> 0 | B25: =IF($A25=1,TEXT((Calc!$C7-60)/1440,"hh:mm")&" – "&TEXT(Calc!$C7/1440,"hh:mm"),IF($A25=2,"TOTAL","")) | C25: =IF($A25=1,_xlfn.LET(_xlpm.s,SUMIFS(Messages!$E:$E,Messages!$D:$D,C$19,Messages!$K:$K,">="&Calc!$B7,Messages!$K:$K,"<"&Calc!$C7),IF(_xlpm.s=0,"",_xlpm.s)),IF($A25=2,SUMIFS(Messages!$E:$E,Messages!$D:$D,C$19),IF($A25=3,IFERROR(TEXT(SUMIFS(Messages!$E:$E,Messages!$D:$D,C$19)/SUM(Messages!$E:$E),"0%"),""),""))) | D25: =IF($A25=1,_xlfn.LET(_xlpm.s,SUMIFS(Messages!$E:$E,Messages!$D:$D,D$19,Messages!$K:$K,">="&Calc!$B7,Messages!$K:$K,"<"&Calc!$C7),IF(_xlpm.s=0,"",_xlpm.s)),IF($A25=2,SUMIFS(Messages!$E:$E,Messages!$D:$D,D$19),IF($A25=3,IFERROR(TEXT(SUMIFS(Messages!$E:$E,Messages!$D:$D,D$19)/SUM(Messages!$E:$E),"0%"),""),""))) | E25: =IF($A25=1,_xlfn.LET(_xlpm.s,SUMIFS(Messages!$E:$E,Messages!$D:$D,E$19,Messages!$K:$K,">="&Calc!$B7,Messages!$K:$K,"<"&Calc!$C7),IF(_xlpm.s=0,"",_xlpm.s)),IF($A25=2,SUMIFS(Messages!$E:$E,Messages!$D:$D,E$19),IF($A25=3,IFERROR(TEXT(SUMIFS(Messages!$E:$E,Messages!$D:$D,E$19)/SUM(Messages!$E:$E),"0%"),""),""))) | F25: =IF($A25=1,_xlfn.LET(_xlpm.s,SUMIFS(Messages!$E:$E,Messages!$D:$D,F$19,Messages!$K:$K,">="&Calc!$B7,Messages!$K:$K,"<"&Calc!$C7),IF(_xlpm.s=0,"",_xlpm.s)),IF($A25=2,SUMIFS(Messages!$E:$E,Messages!$D:$D,F$19),IF($A25=3,IFERROR(TEXT(SUMIFS(Messages!$E:$E,Messages!$D:$D,F$19)/SUM(Messages!$E:$E),"0%"),""),""))) | G25: =IF($A25=1,_xlfn.LET(_xlpm.s,SUMIFS(Messages!$E:$E,Messages!$D:$D,G$19,Messages!$K:$K,">="&Calc!$B7,Messages!$K:$K,"<"&Calc!$C7),IF(_xlpm.s=0,"",_xlpm.s)),IF($A25=2,SUMIFS(Messages!$E:$E,Messages!$D:$D,G$19),IF($A25=3,IFERROR(TEXT(SUMIFS(Messages!$E:$E,Messages!$D:$D,G$19)/SUM(Messages!$E:$E),"0%"),""),""))) | H25: =IF($A25=1,COUNTIFS(Messages!$K:$K,">="&Calc!$B7,Messages!$K:$K,"<"&Calc!$C7),IF($A25=2,COUNT(Messages!$K:$K),"")) | I25: =IF($A25=1,SUMIFS(Messages!$E:$E,Messages!$K:$K,">="&Calc!$B7,Messages!$K:$K,"<"&Calc!$C7),IF($A25=2,SUM(Messages!$E:$E),"")) | J25: =IF(AND($A25=1,$O25<>""),IF($O25<>IF(ROW()=20,ReqInit,Calc!$K6),"Client asked for "&$O25&" m³/h.",""),"") | Q25: =IF($A25>0,$H25,"")
A26: =IF(ROW()-19<=nHours,1,IF(nHours=0,0,IF(ROW()-19=nHours+1,2,0))) -> 0 | B26: =IF($A26=1,TEXT((Calc!$C8-60)/1440,"hh:mm")&" – "&TEXT(Calc!$C8/1440,"hh:mm"),IF($A26=2,"TOTAL","")) | C26: =IF($A26=1,_xlfn.LET(_xlpm.s,SUMIFS(Messages!$E:$E,Messages!$D:$D,C$19,Messages!$K:$K,">="&Calc!$B8,Messages!$K:$K,"<"&Calc!$C8),IF(_xlpm.s=0,"",_xlpm.s)),IF($A26=2,SUMIFS(Messages!$E:$E,Messages!$D:$D,C$19),IF($A26=3,IFERROR(TEXT(SUMIFS(Messages!$E:$E,Messages!$D:$D,C$19)/SUM(Messages!$E:$E),"0%"),""),""))) | D26: =IF($A26=1,_xlfn.LET(_xlpm.s,SUMIFS(Messages!$E:$E,Messages!$D:$D,D$19,Messages!$K:$K,">="&Calc!$B8,Messages!$K:$K,"<"&Calc!$C8),IF(_xlpm.s=0,"",_xlpm.s)),IF($A26=2,SUMIFS(Messages!$E:$E,Messages!$D:$D,D$19),IF($A26=3,IFERROR(TEXT(SUMIFS(Messages!$E:$E,Messages!$D:$D,D$19)/SUM(Messages!$E:$E),"0%"),""),""))) | E26: =IF($A26=1,_xlfn.LET(_xlpm.s,SUMIFS(Messages!$E:$E,Messages!$D:$D,E$19,Messages!$K:$K,">="&Calc!$B8,Messages!$K:$K,"<"&Calc!$C8),IF(_xlpm.s=0,"",_xlpm.s)),IF($A26=2,SUMIFS(Messages!$E:$E,Messages!$D:$D,E$19),IF($A26=3,IFERROR(TEXT(SUMIFS(Messages!$E:$E,Messages!$D:$D,E$19)/SUM(Messages!$E:$E),"0%"),""),""))) | F26: =IF($A26=1,_xlfn.LET(_xlpm.s,SUMIFS(Messages!$E:$E,Messages!$D:$D,F$19,Messages!$K:$K,">="&Calc!$B8,Messages!$K:$K,"<"&Calc!$C8),IF(_xlpm.s=0,"",_xlpm.s)),IF($A26=2,SUMIFS(Messages!$E:$E,Messages!$D:$D,F$19),IF($A26=3,IFERROR(TEXT(SUMIFS(Messages!$E:$E,Messages!$D:$D,F$19)/SUM(Messages!$E:$E),"0%"),""),""))) | G26: =IF($A26=1,_xlfn.LET(_xlpm.s,SUMIFS(Messages!$E:$E,Messages!$D:$D,G$19,Messages!$K:$K,">="&Calc!$B8,Messages!$K:$K,"<"&Calc!$C8),IF(_xlpm.s=0,"",_xlpm.s)),IF($A26=2,SUMIFS(Messages!$E:$E,Messages!$D:$D,G$19),IF($A26=3,IFERROR(TEXT(SUMIFS(Messages!$E:$E,Messages!$D:$D,G$19)/SUM(Messages!$E:$E),"0%"),""),""))) | H26: =IF($A26=1,COUNTIFS(Messages!$K:$K,">="&Calc!$B8,Messages!$K:$K,"<"&Calc!$C8),IF($A26=2,COUNT(Messages!$K:$K),"")) | I26: =IF($A26=1,SUMIFS(Messages!$E:$E,Messages!$K:$K,">="&Calc!$B8,Messages!$K:$K,"<"&Calc!$C8),IF($A26=2,SUM(Messages!$E:$E),"")) | J26: =IF(AND($A26=1,$O26<>""),IF($O26<>IF(ROW()=20,ReqInit,Calc!$K7),"Client asked for "&$O26&" m³/h.",""),"") | Q26: =IF($A26>0,$H26,"")
A27: =IF(ROW()-19<=nHours,1,IF(nHours=0,0,IF(ROW()-19=nHours+1,2,0))) -> 0 | B27: =IF($A27=1,TEXT((Calc!$C9-60)/1440,"hh:mm")&" – "&TEXT(Calc!$C9/1440,"hh:mm"),IF($A27=2,"TOTAL","")) | C27: =IF($A27=1,_xlfn.LET(_xlpm.s,SUMIFS(Messages!$E:$E,Messages!$D:$D,C$19,Messages!$K:$K,">="&Calc!$B9,Messages!$K:$K,"<"&Calc!$C9),IF(_xlpm.s=0,"",_xlpm.s)),IF($A27=2,SUMIFS(Messages!$E:$E,Messages!$D:$D,C$19),IF($A27=3,IFERROR(TEXT(SUMIFS(Messages!$E:$E,Messages!$D:$D,C$19)/SUM(Messages!$E:$E),"0%"),""),""))) | D27: =IF($A27=1,_xlfn.LET(_xlpm.s,SUMIFS(Messages!$E:$E,Messages!$D:$D,D$19,Messages!$K:$K,">="&Calc!$B9,Messages!$K:$K,"<"&Calc!$C9),IF(_xlpm.s=0,"",_xlpm.s)),IF($A27=2,SUMIFS(Messages!$E:$E,Messages!$D:$D,D$19),IF($A27=3,IFERROR(TEXT(SUMIFS(Messages!$E:$E,Messages!$D:$D,D$19)/SUM(Messages!$E:$E),"0%"),""),""))) | E27: =IF($A27=1,_xlfn.LET(_xlpm.s,SUMIFS(Messages!$E:$E,Messages!$D:$D,E$19,Messages!$K:$K,">="&Calc!$B9,Messages!$K:$K,"<"&Calc!$C9),IF(_xlpm.s=0,"",_xlpm.s)),IF($A27=2,SUMIFS(Messages!$E:$E,Messages!$D:$D,E$19),IF($A27=3,IFERROR(TEXT(SUMIFS(Messages!$E:$E,Messages!$D:$D,E$19)/SUM(Messages!$E:$E),"0%"),""),""))) | F27: =IF($A27=1,_xlfn.LET(_xlpm.s,SUMIFS(Messages!$E:$E,Messages!$D:$D,F$19,Messages!$K:$K,">="&Calc!$B9,Messages!$K:$K,"<"&Calc!$C9),IF(_xlpm.s=0,"",_xlpm.s)),IF($A27=2,SUMIFS(Messages!$E:$E,Messages!$D:$D,F$19),IF($A27=3,IFERROR(TEXT(SUMIFS(Messages!$E:$E,Messages!$D:$D,F$19)/SUM(Messages!$E:$E),"0%"),""),""))) | G27: =IF($A27=1,_xlfn.LET(_xlpm.s,SUMIFS(Messages!$E:$E,Messages!$D:$D,G$19,Messages!$K:$K,">="&Calc!$B9,Messages!$K:$K,"<"&Calc!$C9),IF(_xlpm.s=0,"",_xlpm.s)),IF($A27=2,SUMIFS(Messages!$E:$E,Messages!$D:$D,G$19),IF($A27=3,IFERROR(TEXT(SUMIFS(Messages!$E:$E,Messages!$D:$D,G$19)/SUM(Messages!$E:$E),"0%"),""),""))) | H27: =IF($A27=1,COUNTIFS(Messages!$K:$K,">="&Calc!$B9,Messages!$K:$K,"<"&Calc!$C9),IF($A27=2,COUNT(Messages!$K:$K),"")) | I27: =IF($A27=1,SUMIFS(Messages!$E:$E,Messages!$K:$K,">="&Calc!$B9,Messages!$K:$K,"<"&Calc!$C9),IF($A27=2,SUM(Messages!$E:$E),"")) | J27: =IF(AND($A27=1,$O27<>""),IF($O27<>IF(ROW()=20,ReqInit,Calc!$K8),"Client asked for "&$O27&" m³/h.",""),"") | Q27: =IF($A27>0,$H27,"")
A28: =IF(ROW()-19<=nHours,1,IF(nHours=0,0,IF(ROW()-19=nHours+1,2,0))) -> 0 | B28: =IF($A28=1,TEXT((Calc!$C10-60)/1440,"hh:mm")&" – "&TEXT(Calc!$C10/1440,"hh:mm"),IF($A28=2,"TOTAL","")) | C28: =IF($A28=1,_xlfn.LET(_xlpm.s,SUMIFS(Messages!$E:$E,Messages!$D:$D,C$19,Messages!$K:$K,">="&Calc!$B10,Messages!$K:$K,"<"&Calc!$C10),IF(_xlpm.s=0,"",_xlpm.s)),IF($A28=2,SUMIFS(Messages!$E:$E,Messages!$D:$D,C$19),IF($A28=3,IFERROR(TEXT(SUMIFS(Messages!$E:$E,Messages!$D:$D,C$19)/SUM(Messages!$E:$E),"0%"),""),""))) | D28: =IF($A28=1,_xlfn.LET(_xlpm.s,SUMIFS(Messages!$E:$E,Messages!$D:$D,D$19,Messages!$K:$K,">="&Calc!$B10,Messages!$K:$K,"<"&Calc!$C10),IF(_xlpm.s=0,"",_xlpm.s)),IF($A28=2,SUMIFS(Messages!$E:$E,Messages!$D:$D,D$19),IF($A28=3,IFERROR(TEXT(SUMIFS(Messages!$E:$E,Messages!$D:$D,D$19)/SUM(Messages!$E:$E),"0%"),""),""))) | E28: =IF($A28=1,_xlfn.LET(_xlpm.s,SUMIFS(Messages!$E:$E,Messages!$D:$D,E$19,Messages!$K:$K,">="&Calc!$B10,Messages!$K:$K,"<"&Calc!$C10),IF(_xlpm.s=0,"",_xlpm.s)),IF($A28=2,SUMIFS(Messages!$E:$E,Messages!$D:$D,E$19),IF($A28=3,IFERROR(TEXT(SUMIFS(Messages!$E:$E,Messages!$D:$D,E$19)/SUM(Messages!$E:$E),"0%"),""),""))) | F28: =IF($A28=1,_xlfn.LET(_xlpm.s,SUMIFS(Messages!$E:$E,Messages!$D:$D,F$19,Messages!$K:$K,">="&Calc!$B10,Messages!$K:$K,"<"&Calc!$C10),IF(_xlpm.s=0,"",_xlpm.s)),IF($A28=2,SUMIFS(Messages!$E:$E,Messages!$D:$D,F$19),IF($A28=3,IFERROR(TEXT(SUMIFS(Messages!$E:$E,Messages!$D:$D,F$19)/SUM(Messages!$E:$E),"0%"),""),""))) | G28: =IF($A28=1,_xlfn.LET(_xlpm.s,SUMIFS(Messages!$E:$E,Messages!$D:$D,G$19,Messages!$K:$K,">="&Calc!$B10,Messages!$K:$K,"<"&Calc!$C10),IF(_xlpm.s=0,"",_xlpm.s)),IF($A28=2,SUMIFS(Messages!$E:$E,Messages!$D:$D,G$19),IF($A28=3,IFERROR(TEXT(SUMIFS(Messages!$E:$E,Messages!$D:$D,G$19)/SUM(Messages!$E:$E),"0%"),""),""))) | H28: =IF($A28=1,COUNTIFS(Messages!$K:$K,">="&Calc!$B10,Messages!$K:$K,"<"&Calc!$C10),IF($A28=2,COUNT(Messages!$K:$K),"")) | I28: =IF($A28=1,SUMIFS(Messages!$E:$E,Messages!$K:$K,">="&Calc!$B10,Messages!$K:$K,"<"&Calc!$C10),IF($A28=2,SUM(Messages!$E:$E),"")) | J28: =IF(AND($A28=1,$O28<>""),IF($O28<>IF(ROW()=20,ReqInit,Calc!$K9),"Client asked for "&$O28&" m³/h.",""),"") | Q28: =IF($A28>0,$H28,"")
A29: =IF(ROW()-19<=nHours,1,IF(nHours=0,0,IF(ROW()-19=nHours+1,2,0))) -> 0 | B29: =IF($A29=1,TEXT((Calc!$C11-60)/1440,"hh:mm")&" – "&TEXT(Calc!$C11/1440,"hh:mm"),IF($A29=2,"TOTAL","")) | C29: =IF($A29=1,_xlfn.LET(_xlpm.s,SUMIFS(Messages!$E:$E,Messages!$D:$D,C$19,Messages!$K:$K,">="&Calc!$B11,Messages!$K:$K,"<"&Calc!$C11),IF(_xlpm.s=0,"",_xlpm.s)),IF($A29=2,SUMIFS(Messages!$E:$E,Messages!$D:$D,C$19),IF($A29=3,IFERROR(TEXT(SUMIFS(Messages!$E:$E,Messages!$D:$D,C$19)/SUM(Messages!$E:$E),"0%"),""),""))) | D29: =IF($A29=1,_xlfn.LET(_xlpm.s,SUMIFS(Messages!$E:$E,Messages!$D:$D,D$19,Messages!$K:$K,">="&Calc!$B11,Messages!$K:$K,"<"&Calc!$C11),IF(_xlpm.s=0,"",_xlpm.s)),IF($A29=2,SUMIFS(Messages!$E:$E,Messages!$D:$D,D$19),IF($A29=3,IFERROR(TEXT(SUMIFS(Messages!$E:$E,Messages!$D:$D,D$19)/SUM(Messages!$E:$E),"0%"),""),""))) | E29: =IF($A29=1,_xlfn.LET(_xlpm.s,SUMIFS(Messages!$E:$E,Messages!$D:$D,E$19,Messages!$K:$K,">="&Calc!$B11,Messages!$K:$K,"<"&Calc!$C11),IF(_xlpm.s=0,"",_xlpm.s)),IF($A29=2,SUMIFS(Messages!$E:$E,Messages!$D:$D,E$19),IF($A29=3,IFERROR(TEXT(SUMIFS(Messages!$E:$E,Messages!$D:$D,E$19)/SUM(Messages!$E:$E),"0%"),""),""))) | F29: =IF($A29=1,_xlfn.LET(_xlpm.s,SUMIFS(Messages!$E:$E,Messages!$D:$D,F$19,Messages!$K:$K,">="&Calc!$B11,Messages!$K:$K,"<"&Calc!$C11),IF(_xlpm.s=0,"",_xlpm.s)),IF($A29=2,SUMIFS(Messages!$E:$E,Messages!$D:$D,F$19),IF($A29=3,IFERROR(TEXT(SUMIFS(Messages!$E:$E,Messages!$D:$D,F$19)/SUM(Messages!$E:$E),"0%"),""),""))) | G29: =IF($A29=1,_xlfn.LET(_xlpm.s,SUMIFS(Messages!$E:$E,Messages!$D:$D,G$19,Messages!$K:$K,">="&Calc!$B11,Messages!$K:$K,"<"&Calc!$C11),IF(_xlpm.s=0,"",_xlpm.s)),IF($A29=2,SUMIFS(Messages!$E:$E,Messages!$D:$D,G$19),IF($A29=3,IFERROR(TEXT(SUMIFS(Messages!$E:$E,Messages!$D:$D,G$19)/SUM(Messages!$E:$E),"0%"),""),""))) | H29: =IF($A29=1,COUNTIFS(Messages!$K:$K,">="&Calc!$B11,Messages!$K:$K,"<"&Calc!$C11),IF($A29=2,COUNT(Messages!$K:$K),"")) | I29: =IF($A29=1,SUMIFS(Messages!$E:$E,Messages!$K:$K,">="&Calc!$B11,Messages!$K:$K,"<"&Calc!$C11),IF($A29=2,SUM(Messages!$E:$E),"")) | J29: =IF(AND($A29=1,$O29<>""),IF($O29<>IF(ROW()=20,ReqInit,Calc!$K10),"Client asked for "&$O29&" m³/h.",""),"") | Q29: =IF($A29>0,$H29,"")
A30: =IF(ROW()-19<=nHours,1,IF(nHours=0,0,IF(ROW()-19=nHours+1,2,0))) -> 0 | B30: =IF($A30=1,TEXT((Calc!$C12-60)/1440,"hh:mm")&" – "&TEXT(Calc!$C12/1440,"hh:mm"),IF($A30=2,"TOTAL","")) | C30: =IF($A30=1,_xlfn.LET(_xlpm.s,SUMIFS(Messages!$E:$E,Messages!$D:$D,C$19,Messages!$K:$K,">="&Calc!$B12,Messages!$K:$K,"<"&Calc!$C12),IF(_xlpm.s=0,"",_xlpm.s)),IF($A30=2,SUMIFS(Messages!$E:$E,Messages!$D:$D,C$19),IF($A30=3,IFERROR(TEXT(SUMIFS(Messages!$E:$E,Messages!$D:$D,C$19)/SUM(Messages!$E:$E),"0%"),""),""))) | D30: =IF($A30=1,_xlfn.LET(_xlpm.s,SUMIFS(Messages!$E:$E,Messages!$D:$D,D$19,Messages!$K:$K,">="&Calc!$B12,Messages!$K:$K,"<"&Calc!$C12),IF(_xlpm.s=0,"",_xlpm.s)),IF($A30=2,SUMIFS(Messages!$E:$E,Messages!$D:$D,D$19),IF($A30=3,IFERROR(TEXT(SUMIFS(Messages!$E:$E,Messages!$D:$D,D$19)/SUM(Messages!$E:$E),"0%"),""),""))) | E30: =IF($A30=1,_xlfn.LET(_xlpm.s,SUMIFS(Messages!$E:$E,Messages!$D:$D,E$19,Messages!$K:$K,">="&Calc!$B12,Messages!$K:$K,"<"&Calc!$C12),IF(_xlpm.s=0,"",_xlpm.s)),IF($A30=2,SUMIFS(Messages!$E:$E,Messages!$D:$D,E$19),IF($A30=3,IFERROR(TEXT(SUMIFS(Messages!$E:$E,Messages!$D:$D,E$19)/SUM(Messages!$E:$E),"0%"),""),""))) | F30: =IF($A30=1,_xlfn.LET(_xlpm.s,SUMIFS(Messages!$E:$E,Messages!$D:$D,F$19,Messages!$K:$K,">="&Calc!$B12,Messages!$K:$K,"<"&Calc!$C12),IF(_xlpm.s=0,"",_xlpm.s)),IF($A30=2,SUMIFS(Messages!$E:$E,Messages!$D:$D,F$19),IF($A30=3,IFERROR(TEXT(SUMIFS(Messages!$E:$E,Messages!$D:$D,F$19)/SUM(Messages!$E:$E),"0%"),""),""))) | G30: =IF($A30=1,_xlfn.LET(_xlpm.s,SUMIFS(Messages!$E:$E,Messages!$D:$D,G$19,Messages!$K:$K,">="&Calc!$B12,Messages!$K:$K,"<"&Calc!$C12),IF(_xlpm.s=0,"",_xlpm.s)),IF($A30=2,SUMIFS(Messages!$E:$E,Messages!$D:$D,G$19),IF($A30=3,IFERROR(TEXT(SUMIFS(Messages!$E:$E,Messages!$D:$D,G$19)/SUM(Messages!$E:$E),"0%"),""),""))) | H30: =IF($A30=1,COUNTIFS(Messages!$K:$K,">="&Calc!$B12,Messages!$K:$K,"<"&Calc!$C12),IF($A30=2,COUNT(Messages!$K:$K),"")) | I30: =IF($A30=1,SUMIFS(Messages!$E:$E,Messages!$K:$K,">="&Calc!$B12,Messages!$K:$K,"<"&Calc!$C12),IF($A30=2,SUM(Messages!$E:$E),"")) | J30: =IF(AND($A30=1,$O30<>""),IF($O30<>IF(ROW()=20,ReqInit,Calc!$K11),"Client asked for "&$O30&" m³/h.",""),"") | Q30: =IF($A30>0,$H30,"")
A31: =IF(ROW()-19<=nHours,1,IF(nHours=0,0,IF(ROW()-19=nHours+1,2,0))) -> 0 | B31: =IF($A31=1,TEXT((Calc!$C13-60)/1440,"hh:mm")&" – "&TEXT(Calc!$C13/1440,"hh:mm"),IF($A31=2,"TOTAL","")) | C31: =IF($A31=1,_xlfn.LET(_xlpm.s,SUMIFS(Messages!$E:$E,Messages!$D:$D,C$19,Messages!$K:$K,">="&Calc!$B13,Messages!$K:$K,"<"&Calc!$C13),IF(_xlpm.s=0,"",_xlpm.s)),IF($A31=2,SUMIFS(Messages!$E:$E,Messages!$D:$D,C$19),IF($A31=3,IFERROR(TEXT(SUMIFS(Messages!$E:$E,Messages!$D:$D,C$19)/SUM(Messages!$E:$E),"0%"),""),""))) | D31: =IF($A31=1,_xlfn.LET(_xlpm.s,SUMIFS(Messages!$E:$E,Messages!$D:$D,D$19,Messages!$K:$K,">="&Calc!$B13,Messages!$K:$K,"<"&Calc!$C13),IF(_xlpm.s=0,"",_xlpm.s)),IF($A31=2,SUMIFS(Messages!$E:$E,Messages!$D:$D,D$19),IF($A31=3,IFERROR(TEXT(SUMIFS(Messages!$E:$E,Messages!$D:$D,D$19)/SUM(Messages!$E:$E),"0%"),""),""))) | E31: =IF($A31=1,_xlfn.LET(_xlpm.s,SUMIFS(Messages!$E:$E,Messages!$D:$D,E$19,Messages!$K:$K,">="&Calc!$B13,Messages!$K:$K,"<"&Calc!$C13),IF(_xlpm.s=0,"",_xlpm.s)),IF($A31=2,SUMIFS(Messages!$E:$E,Messages!$D:$D,E$19),IF($A31=3,IFERROR(TEXT(SUMIFS(Messages!$E:$E,Messages!$D:$D,E$19)/SUM(Messages!$E:$E),"0%"),""),""))) | F31: =IF($A31=1,_xlfn.LET(_xlpm.s,SUMIFS(Messages!$E:$E,Messages!$D:$D,F$19,Messages!$K:$K,">="&Calc!$B13,Messages!$K:$K,"<"&Calc!$C13),IF(_xlpm.s=0,"",_xlpm.s)),IF($A31=2,SUMIFS(Messages!$E:$E,Messages!$D:$D,F$19),IF($A31=3,IFERROR(TEXT(SUMIFS(Messages!$E:$E,Messages!$D:$D,F$19)/SUM(Messages!$E:$E),"0%"),""),""))) | G31: =IF($A31=1,_xlfn.LET(_xlpm.s,SUMIFS(Messages!$E:$E,Messages!$D:$D,G$19,Messages!$K:$K,">="&Calc!$B13,Messages!$K:$K,"<"&Calc!$C13),IF(_xlpm.s=0,"",_xlpm.s)),IF($A31=2,SUMIFS(Messages!$E:$E,Messages!$D:$D,G$19),IF($A31=3,IFERROR(TEXT(SUMIFS(Messages!$E:$E,Messages!$D:$D,G$19)/SUM(Messages!$E:$E),"0%"),""),""))) | H31: =IF($A31=1,COUNTIFS(Messages!$K:$K,">="&Calc!$B13,Messages!$K:$K,"<"&Calc!$C13),IF($A31=2,COUNT(Messages!$K:$K),"")) | I31: =IF($A31=1,SUMIFS(Messages!$E:$E,Messages!$K:$K,">="&Calc!$B13,Messages!$K:$K,"<"&Calc!$C13),IF($A31=2,SUM(Messages!$E:$E),"")) | J31: =IF(AND($A31=1,$O31<>""),IF($O31<>IF(ROW()=20,ReqInit,Calc!$K12),"Client asked for "&$O31&" m³/h.",""),"") | Q31: =IF($A31>0,$H31,"")
... A69: =IF(ROW()-19<=nHours,1,IF(nHours=0,0,IF(ROW()-19=nHours+1,2,0))) -> 0 | B69: =IF($A69=1,TEXT((Calc!$C51-60)/1440,"hh:mm")&" – "&TEXT(Calc!$C51/1440,"hh:mm"),IF($A69=2,"TOTAL","")) | C69: =IF($A69=1,_xlfn.LET(_xlpm.s,SUMIFS(Messages!$E:$E,Messages!$D:$D,C$19,Messages!$K:$K,">="&Calc!$B51,Messages!$K:$K,"<"&Calc!$C51),IF(_xlpm.s=0,"",_xlpm.s)),IF($A69=2,SUMIFS(Messages!$E:$E,Messages!$D:$D,C$19),IF($A69=3,IFERROR(TEXT(SUMIFS(Messages!$E:$E,Messages!$D:$D,C$19)/SUM(Messages!$E:$E),"0%"),""),""))) | D69: =IF($A69=1,_xlfn.LET(_xlpm.s,SUMIFS(Messages!$E:$E,Messages!$D:$D,D$19,Messages!$K:$K,">="&Calc!$B51,Messages!$K:$K,"<"&Calc!$C51),IF(_xlpm.s=0,"",_xlpm.s)),IF($A69=2,SUMIFS(Messages!$E:$E,Messages!$D:$D,D$19),IF($A69=3,IFERROR(TEXT(SUMIFS(Messages!$E:$E,Messages!$D:$D,D$19)/SUM(Messages!$E:$E),"0%"),""),""))) | E69: =IF($A69=1,_xlfn.LET(_xlpm.s,SUMIFS(Messages!$E:$E,Messages!$D:$D,E$19,Messages!$K:$K,">="&Calc!$B51,Messages!$K:$K,"<"&Calc!$C51),IF(_xlpm.s=0,"",_xlpm.s)),IF($A69=2,SUMIFS(Messages!$E:$E,Messages!$D:$D,E$19),IF($A69=3,IFERROR(TEXT(SUMIFS(Messages!$E:$E,Messages!$D:$D,E$19)/SUM(Messages!$E:$E),"0%"),""),""))) | F69: =IF($A69=1,_xlfn.LET(_xlpm.s,SUMIFS(Messages!$E:$E,Messages!$D:$D,F$19,Messages!$K:$K,">="&Calc!$B51,Messages!$K:$K,"<"&Calc!$C51),IF(_xlpm.s=0,"",_xlpm.s)),IF($A69=2,SUMIFS(Messages!$E:$E,Messages!$D:$D,F$19),IF($A69=3,IFERROR(TEXT(SUMIFS(Messages!$E:$E,Messages!$D:$D,F$19)/SUM(Messages!$E:$E),"0%"),""),""))) | G69: =IF($A69=1,_xlfn.LET(_xlpm.s,SUMIFS(Messages!$E:$E,Messages!$D:$D,G$19,Messages!$K:$K,">="&Calc!$B51,Messages!$K:$K,"<"&Calc!$C51),IF(_xlpm.s=0,"",_xlpm.s)),IF($A69=2,SUMIFS(Messages!$E:$E,Messages!$D:$D,G$19),IF($A69=3,IFERROR(TEXT(SUMIFS(Messages!$E:$E,Messages!$D:$D,G$19)/SUM(Messages!$E:$E),"0%"),""),""))) | H69: =IF($A69=1,COUNTIFS(Messages!$K:$K,">="&Calc!$B51,Messages!$K:$K,"<"&Calc!$C51),IF($A69=2,COUNT(Messages!$K:$K),"")) | I69: =IF($A69=1,SUMIFS(Messages!$E:$E,Messages!$K:$K,">="&Calc!$B51,Messages!$K:$K,"<"&Calc!$C51),IF($A69=2,SUM(Messages!$E:$E),"")) | J69: =IF(AND($A69=1,$O69<>""),IF($O69<>IF(ROW()=20,ReqInit,Calc!$K50),"Client asked for "&$O69&" m³/h.",""),"") | Q69: =IF($A69>0,$H69,"")

Sheet Messages
A1: S/N | B1: MESSAGE (paste here) | C1: TIME | D1: PLANT | E1: QTY m³ | F1: REJECTED ✎ (x or m³) | G1: CHECK | H1: clean text | I1: raw time | J1: rej m³ | K1: minute | L1: serial | M1: dup
A2: =IF(OR(B2="",M2,G2="— ignored"),"",MAX(A$1:A1)+1) | C2: =IF(I2="","",ROUND((I2+0.5*MAX(0,CEILING(ROUND((MAX(C$1:C1)-1/48-I2)/0.5,6),1)))*1440,0)/1440) | D2: {=IF(H2="","",IFERROR(INDEX(Log!$C$19:$G$19,VALUE(MID(H2,FIND("#",H2)+1,1))),""))} | E2: {=IF(OR(H2="",M2),"",IFERROR(_xlfn.LET(_xlpm.t,SUBSTITUTE(UPPER(H2),"م","M"),_xlpm.u,SUBSTITUTE(_xlpm.t," ",""),_xlpm.s,_xlfn.SEQUENCE(LEN(_xlpm.u)),_xlpm.p,MIN(IF((MID(_xlpm.u,_xlpm.s,1)="M")*ISNUMBER(-MID(_xlpm.u,_xlpm.s-1,1)),_xlpm.s)),_xlpm.k,LEN(LEFT(_xlpm.u,_xlpm.p))-LEN(SUBSTITUTE(LEFT(_xlpm.u,_xlpm.p),"M","")),_xlpm.pos,FIND(CHAR(1),SUBSTITUTE(_xlpm.t,"M",CHAR(1),_xlpm.k)),_xlpm.b,TRIM(LEFT(_xlpm.t,_xlpm.pos-1)),_xlpm.tok,TRIM(RIGHT(SUBSTITUTE(_xlpm.b," ",REPT(" ",30)),30)),_xlpm.z,_xlfn.SEQUENCE(LEN(_xlpm.tok)),_xlpm.q,MAX(IF(ISNUMBER(FIND(MID(_xlpm.tok,_xlpm.z,1),"0123456789.")),0,_xlpm.z)),_xlpm.num,MID(_xlpm.tok,_xlpm.q+1,30),VALUE(IF(LEFT(_xlpm.num,1)=".",MID(_xlpm.num,2,30),_xlpm.num))),""))} | G2: =IF(B2="","",IF(M2,"⚠ Duplicate (not counted)",IF(AND(I2="",D2="",E2=""),"— ignored",IF(C2="","⚠ Time",IF(D2="","⚠ Plant",IF(E2="","⚠ Quantity",IF(AND(ISNUMBER(L2),COUNTIF(L$1:L1,L2)>0),"⚠ Same serial "&L2,IF(AND(ISNUMBER(L2),L2>MIN($L$2:$L$1001),COUNTIF($L$2:$L$1001,L2-1)=0,COUNTIF($L$2:$L$1001,L2-2)<2),"⚠ Missing serial "&(L2-1),IF(AND(MAX(K$1:K1)>0,N(K2)-MAX(K$1:K1)>180),"⚠ Gap > 3h",IF(C2-I2>=0.99,"next day",IF(C2-I2>0.4,"12h → 24h",""))))))))))) | H2: =IF(B2="","",_xlfn.LET(_xlpm.t,TRIM(B2),IF(LEFT(_xlpm.t,1)="[",IFERROR(TRIM(MID(_xlpm.t,FIND(": ",_xlpm.t,FIND("]",_xlpm.t))+2,500)),_xlpm.t),_xlpm.t))) | I2: =IF(H2="","",IFERROR(TIMEVALUE(TRIM(SUBSTITUTE(SUBSTITUTE(MID(H2,SEARCH(":",H2)-2,5),".",""),"*",""))),"")) | J2: =IF(OR(B2="",F2="",M2),0,IF(ISNUMBER(F2),F2,N(E2))) -> 0 | K2: =IF(OR(C2="",M2),"",ROUND(C2*1440,0)) | L2: =IF(OR(H2="",AND(I2="",D2="")),"",IFERROR(_xlfn.LET(_xlpm.t,TRIM(SUBSTITUTE(SUBSTITUTE(H2,"*",""),"_","")),VALUE(SUBSTITUTE(LEFT(_xlpm.t,FIND(" ",_xlpm.t&" ")-1),".",""))),"")) | M2: {=IF(H2="",FALSE,SUMPRODUCT(--(H$1:H1=H2))>0)} -> FALSE | O2: طريقة الاستخدام:
A3: =IF(OR(B3="",M3,G3="— ignored"),"",MAX(A$1:A2)+1) | C3: =IF(I3="","",ROUND((I3+0.5*MAX(0,CEILING(ROUND((MAX(C$1:C2)-1/48-I3)/0.5,6),1)))*1440,0)/1440) | D3: {=IF(H3="","",IFERROR(INDEX(Log!$C$19:$G$19,VALUE(MID(H3,FIND("#",H3)+1,1))),""))} | E3: {=IF(OR(H3="",M3),"",IFERROR(_xlfn.LET(_xlpm.t,SUBSTITUTE(UPPER(H3),"م","M"),_xlpm.u,SUBSTITUTE(_xlpm.t," ",""),_xlpm.s,_xlfn.SEQUENCE(LEN(_xlpm.u)),_xlpm.p,MIN(IF((MID(_xlpm.u,_xlpm.s,1)="M")*ISNUMBER(-MID(_xlpm.u,_xlpm.s-1,1)),_xlpm.s)),_xlpm.k,LEN(LEFT(_xlpm.u,_xlpm.p))-LEN(SUBSTITUTE(LEFT(_xlpm.u,_xlpm.p),"M","")),_xlpm.pos,FIND(CHAR(1),SUBSTITUTE(_xlpm.t,"M",CHAR(1),_xlpm.k)),_xlpm.b,TRIM(LEFT(_xlpm.t,_xlpm.pos-1)),_xlpm.tok,TRIM(RIGHT(SUBSTITUTE(_xlpm.b," ",REPT(" ",30)),30)),_xlpm.z,_xlfn.SEQUENCE(LEN(_xlpm.tok)),_xlpm.q,MAX(IF(ISNUMBER(FIND(MID(_xlpm.tok,_xlpm.z,1),"0123456789.")),0,_xlpm.z)),_xlpm.num,MID(_xlpm.tok,_xlpm.q+1,30),VALUE(IF(LEFT(_xlpm.num,1)=".",MID(_xlpm.num,2,30),_xlpm.num))),""))} | G3: =IF(B3="","",IF(M3,"⚠ Duplicate (not counted)",IF(AND(I3="",D3="",E3=""),"— ignored",IF(C3="","⚠ Time",IF(D3="","⚠ Plant",IF(E3="","⚠ Quantity",IF(AND(ISNUMBER(L3),COUNTIF(L$1:L2,L3)>0),"⚠ Same serial "&L3,IF(AND(ISNUMBER(L3),L3>MIN($L$2:$L$1001),COUNTIF($L$2:$L$1001,L3-1)=0,COUNTIF($L$2:$L$1001,L3-2)<2),"⚠ Missing serial "&(L3-1),IF(AND(MAX(K$1:K2)>0,N(K3)-MAX(K$1:K2)>180),"⚠ Gap > 3h",IF(C3-I3>=0.99,"next day",IF(C3-I3>0.4,"12h → 24h",""))))))))))) | H3: =IF(B3="","",_xlfn.LET(_xlpm.t,TRIM(B3),IF(LEFT(_xlpm.t,1)="[",IFERROR(TRIM(MID(_xlpm.t,FIND(": ",_xlpm.t,FIND("]",_xlpm.t))+2,500)),_xlpm.t),_xlpm.t))) | I3: =IF(H3="","",IFERROR(TIMEVALUE(TRIM(SUBSTITUTE(SUBSTITUTE(MID(H3,SEARCH(":",H3)-2,5),".",""),"*",""))),"")) | J3: =IF(OR(B3="",F3="",M3),0,IF(ISNUMBER(F3),F3,N(E3))) -> 0 | K3: =IF(OR(C3="",M3),"",ROUND(C3*1440,0)) | L3: =IF(OR(H3="",AND(I3="",D3="")),"",IFERROR(_xlfn.LET(_xlpm.t,TRIM(SUBSTITUTE(SUBSTITUTE(H3,"*",""),"_","")),VALUE(SUBSTITUTE(LEFT(_xlpm.t,FIND(" ",_xlpm.t&" ")-1),".",""))),"")) | M3: {=IF(H3="",FALSE,SUMPRODUCT(--(H$1:H2=H3))>0)} -> FALSE | O3: 1) انسخ الرسايل من جروب الواتساب (رسالة أو أكتر مرة واحدة) والزقها في عمود MESSAGE في أول خانة فاضية.
A4: =IF(OR(B4="",M4,G4="— ignored"),"",MAX(A$1:A3)+1) | C4: =IF(I4="","",ROUND((I4+0.5*MAX(0,CEILING(ROUND((MAX(C$1:C3)-1/48-I4)/0.5,6),1)))*1440,0)/1440) | D4: {=IF(H4="","",IFERROR(INDEX(Log!$C$19:$G$19,VALUE(MID(H4,FIND("#",H4)+1,1))),""))} | E4: {=IF(OR(H4="",M4),"",IFERROR(_xlfn.LET(_xlpm.t,SUBSTITUTE(UPPER(H4),"م","M"),_xlpm.u,SUBSTITUTE(_xlpm.t," ",""),_xlpm.s,_xlfn.SEQUENCE(LEN(_xlpm.u)),_xlpm.p,MIN(IF((MID(_xlpm.u,_xlpm.s,1)="M")*ISNUMBER(-MID(_xlpm.u,_xlpm.s-1,1)),_xlpm.s)),_xlpm.k,LEN(LEFT(_xlpm.u,_xlpm.p))-LEN(SUBSTITUTE(LEFT(_xlpm.u,_xlpm.p),"M","")),_xlpm.pos,FIND(CHAR(1),SUBSTITUTE(_xlpm.t,"M",CHAR(1),_xlpm.k)),_xlpm.b,TRIM(LEFT(_xlpm.t,_xlpm.pos-1)),_xlpm.tok,TRIM(RIGHT(SUBSTITUTE(_xlpm.b," ",REPT(" ",30)),30)),_xlpm.z,_xlfn.SEQUENCE(LEN(_xlpm.tok)),_xlpm.q,MAX(IF(ISNUMBER(FIND(MID(_xlpm.tok,_xlpm.z,1),"0123456789.")),0,_xlpm.z)),_xlpm.num,MID(_xlpm.tok,_xlpm.q+1,30),VALUE(IF(LEFT(_xlpm.num,1)=".",MID(_xlpm.num,2,30),_xlpm.num))),""))} | G4: =IF(B4="","",IF(M4,"⚠ Duplicate (not counted)",IF(AND(I4="",D4="",E4=""),"— ignored",IF(C4="","⚠ Time",IF(D4="","⚠ Plant",IF(E4="","⚠ Quantity",IF(AND(ISNUMBER(L4),COUNTIF(L$1:L3,L4)>0),"⚠ Same serial "&L4,IF(AND(ISNUMBER(L4),L4>MIN($L$2:$L$1001),COUNTIF($L$2:$L$1001,L4-1)=0,COUNTIF($L$2:$L$1001,L4-2)<2),"⚠ Missing serial "&(L4-1),IF(AND(MAX(K$1:K3)>0,N(K4)-MAX(K$1:K3)>180),"⚠ Gap > 3h",IF(C4-I4>=0.99,"next day",IF(C4-I4>0.4,"12h → 24h",""))))))))))) | H4: =IF(B4="","",_xlfn.LET(_xlpm.t,TRIM(B4),IF(LEFT(_xlpm.t,1)="[",IFERROR(TRIM(MID(_xlpm.t,FIND(": ",_xlpm.t,FIND("]",_xlpm.t))+2,500)),_xlpm.t),_xlpm.t))) | I4: =IF(H4="","",IFERROR(TIMEVALUE(TRIM(SUBSTITUTE(SUBSTITUTE(MID(H4,SEARCH(":",H4)-2,5),".",""),"*",""))),"")) | J4: =IF(OR(B4="",F4="",M4),0,IF(ISNUMBER(F4),F4,N(E4))) -> 0 | K4: =IF(OR(C4="",M4),"",ROUND(C4*1440,0)) | L4: =IF(OR(H4="",AND(I4="",D4="")),"",IFERROR(_xlfn.LET(_xlpm.t,TRIM(SUBSTITUTE(SUBSTITUTE(H4,"*",""),"_","")),VALUE(SUBSTITUTE(LEFT(_xlpm.t,FIND(" ",_xlpm.t&" ")-1),".",""))),"")) | M4: {=IF(H4="",FALSE,SUMPRODUCT(--(H$1:H3=H4))>0)} -> FALSE | O4: 2) الوقت والمحطة والكمية بيتقروا لوحدهم. لو فيه ⚠ في عمود CHECK صلّح نص الرسالة نفسها.
A5: =IF(OR(B5="",M5,G5="— ignored"),"",MAX(A$1:A4)+1) | C5: =IF(I5="","",ROUND((I5+0.5*MAX(0,CEILING(ROUND((MAX(C$1:C4)-1/48-I5)/0.5,6),1)))*1440,0)/1440) | D5: {=IF(H5="","",IFERROR(INDEX(Log!$C$19:$G$19,VALUE(MID(H5,FIND("#",H5)+1,1))),""))} | E5: {=IF(OR(H5="",M5),"",IFERROR(_xlfn.LET(_xlpm.t,SUBSTITUTE(UPPER(H5),"م","M"),_xlpm.u,SUBSTITUTE(_xlpm.t," ",""),_xlpm.s,_xlfn.SEQUENCE(LEN(_xlpm.u)),_xlpm.p,MIN(IF((MID(_xlpm.u,_xlpm.s,1)="M")*ISNUMBER(-MID(_xlpm.u,_xlpm.s-1,1)),_xlpm.s)),_xlpm.k,LEN(LEFT(_xlpm.u,_xlpm.p))-LEN(SUBSTITUTE(LEFT(_xlpm.u,_xlpm.p),"M","")),_xlpm.pos,FIND(CHAR(1),SUBSTITUTE(_xlpm.t,"M",CHAR(1),_xlpm.k)),_xlpm.b,TRIM(LEFT(_xlpm.t,_xlpm.pos-1)),_xlpm.tok,TRIM(RIGHT(SUBSTITUTE(_xlpm.b," ",REPT(" ",30)),30)),_xlpm.z,_xlfn.SEQUENCE(LEN(_xlpm.tok)),_xlpm.q,MAX(IF(ISNUMBER(FIND(MID(_xlpm.tok,_xlpm.z,1),"0123456789.")),0,_xlpm.z)),_xlpm.num,MID(_xlpm.tok,_xlpm.q+1,30),VALUE(IF(LEFT(_xlpm.num,1)=".",MID(_xlpm.num,2,30),_xlpm.num))),""))} | G5: =IF(B5="","",IF(M5,"⚠ Duplicate (not counted)",IF(AND(I5="",D5="",E5=""),"— ignored",IF(C5="","⚠ Time",IF(D5="","⚠ Plant",IF(E5="","⚠ Quantity",IF(AND(ISNUMBER(L5),COUNTIF(L$1:L4,L5)>0),"⚠ Same serial "&L5,IF(AND(ISNUMBER(L5),L5>MIN($L$2:$L$1001),COUNTIF($L$2:$L$1001,L5-1)=0,COUNTIF($L$2:$L$1001,L5-2)<2),"⚠ Missing serial "&(L5-1),IF(AND(MAX(K$1:K4)>0,N(K5)-MAX(K$1:K4)>180),"⚠ Gap > 3h",IF(C5-I5>=0.99,"next day",IF(C5-I5>0.4,"12h → 24h",""))))))))))) | H5: =IF(B5="","",_xlfn.LET(_xlpm.t,TRIM(B5),IF(LEFT(_xlpm.t,1)="[",IFERROR(TRIM(MID(_xlpm.t,FIND(": ",_xlpm.t,FIND("]",_xlpm.t))+2,500)),_xlpm.t),_xlpm.t))) | I5: =IF(H5="","",IFERROR(TIMEVALUE(TRIM(SUBSTITUTE(SUBSTITUTE(MID(H5,SEARCH(":",H5)-2,5),".",""),"*",""))),"")) | J5: =IF(OR(B5="",F5="",M5),0,IF(ISNUMBER(F5),F5,N(E5))) -> 0 | K5: =IF(OR(C5="",M5),"",ROUND(C5*1440,0)) | L5: =IF(OR(H5="",AND(I5="",D5="")),"",IFERROR(_xlfn.LET(_xlpm.t,TRIM(SUBSTITUTE(SUBSTITUTE(H5,"*",""),"_","")),VALUE(SUBSTITUTE(LEFT(_xlpm.t,FIND(" ",_xlpm.t&" ")-1),".",""))),"")) | M5: {=IF(H5="",FALSE,SUMPRODUCT(--(H$1:H4=H5))>0)} -> FALSE | O5: 3) لو لزقت رسالة مرتين بتتعلّم Duplicate ومبتتحسبش.
A6: =IF(OR(B6="",M6,G6="— ignored"),"",MAX(A$1:A5)+1) | C6: =IF(I6="","",ROUND((I6+0.5*MAX(0,CEILING(ROUND((MAX(C$1:C5)-1/48-I6)/0.5,6),1)))*1440,0)/1440) | D6: {=IF(H6="","",IFERROR(INDEX(Log!$C$19:$G$19,VALUE(MID(H6,FIND("#",H6)+1,1))),""))} | E6: {=IF(OR(H6="",M6),"",IFERROR(_xlfn.LET(_xlpm.t,SUBSTITUTE(UPPER(H6),"م","M"),_xlpm.u,SUBSTITUTE(_xlpm.t," ",""),_xlpm.s,_xlfn.SEQUENCE(LEN(_xlpm.u)),_xlpm.p,MIN(IF((MID(_xlpm.u,_xlpm.s,1)="M")*ISNUMBER(-MID(_xlpm.u,_xlpm.s-1,1)),_xlpm.s)),_xlpm.k,LEN(LEFT(_xlpm.u,_xlpm.p))-LEN(SUBSTITUTE(LEFT(_xlpm.u,_xlpm.p),"M","")),_xlpm.pos,FIND(CHAR(1),SUBSTITUTE(_xlpm.t,"M",CHAR(1),_xlpm.k)),_xlpm.b,TRIM(LEFT(_xlpm.t,_xlpm.pos-1)),_xlpm.tok,TRIM(RIGHT(SUBSTITUTE(_xlpm.b," ",REPT(" ",30)),30)),_xlpm.z,_xlfn.SEQUENCE(LEN(_xlpm.tok)),_xlpm.q,MAX(IF(ISNUMBER(FIND(MID(_xlpm.tok,_xlpm.z,1),"0123456789.")),0,_xlpm.z)),_xlpm.num,MID(_xlpm.tok,_xlpm.q+1,30),VALUE(IF(LEFT(_xlpm.num,1)=".",MID(_xlpm.num,2,30),_xlpm.num))),""))} | G6: =IF(B6="","",IF(M6,"⚠ Duplicate (not counted)",IF(AND(I6="",D6="",E6=""),"— ignored",IF(C6="","⚠ Time",IF(D6="","⚠ Plant",IF(E6="","⚠ Quantity",IF(AND(ISNUMBER(L6),COUNTIF(L$1:L5,L6)>0),"⚠ Same serial "&L6,IF(AND(ISNUMBER(L6),L6>MIN($L$2:$L$1001),COUNTIF($L$2:$L$1001,L6-1)=0,COUNTIF($L$2:$L$1001,L6-2)<2),"⚠ Missing serial "&(L6-1),IF(AND(MAX(K$1:K5)>0,N(K6)-MAX(K$1:K5)>180),"⚠ Gap > 3h",IF(C6-I6>=0.99,"next day",IF(C6-I6>0.4,"12h → 24h",""))))))))))) | H6: =IF(B6="","",_xlfn.LET(_xlpm.t,TRIM(B6),IF(LEFT(_xlpm.t,1)="[",IFERROR(TRIM(MID(_xlpm.t,FIND(": ",_xlpm.t,FIND("]",_xlpm.t))+2,500)),_xlpm.t),_xlpm.t))) | I6: =IF(H6="","",IFERROR(TIMEVALUE(TRIM(SUBSTITUTE(SUBSTITUTE(MID(H6,SEARCH(":",H6)-2,5),".",""),"*",""))),"")) | J6: =IF(OR(B6="",F6="",M6),0,IF(ISNUMBER(F6),F6,N(E6))) -> 0 | K6: =IF(OR(C6="",M6),"",ROUND(C6*1440,0)) | L6: =IF(OR(H6="",AND(I6="",D6="")),"",IFERROR(_xlfn.LET(_xlpm.t,TRIM(SUBSTITUTE(SUBSTITUTE(H6,"*",""),"_","")),VALUE(SUBSTITUTE(LEFT(_xlpm.t,FIND(" ",_xlpm.t&" ")-1),".",""))),"")) | M6: {=IF(H6="",FALSE,SUMPRODUCT(--(H$1:H5=H6))>0)} -> FALSE | O6: 4) العربية المرفوضة: اكتب x في عمود REJECTED (أو عدد الأمتار لو جزء منها).
A7: =IF(OR(B7="",M7,G7="— ignored"),"",MAX(A$1:A6)+1) | C7: =IF(I7="","",ROUND((I7+0.5*MAX(0,CEILING(ROUND((MAX(C$1:C6)-1/48-I7)/0.5,6),1)))*1440,0)/1440) | D7: {=IF(H7="","",IFERROR(INDEX(Log!$C$19:$G$19,VALUE(MID(H7,FIND("#",H7)+1,1))),""))} | E7: {=IF(OR(H7="",M7),"",IFERROR(_xlfn.LET(_xlpm.t,SUBSTITUTE(UPPER(H7),"م","M"),_xlpm.u,SUBSTITUTE(_xlpm.t," ",""),_xlpm.s,_xlfn.SEQUENCE(LEN(_xlpm.u)),_xlpm.p,MIN(IF((MID(_xlpm.u,_xlpm.s,1)="M")*ISNUMBER(-MID(_xlpm.u,_xlpm.s-1,1)),_xlpm.s)),_xlpm.k,LEN(LEFT(_xlpm.u,_xlpm.p))-LEN(SUBSTITUTE(LEFT(_xlpm.u,_xlpm.p),"M","")),_xlpm.pos,FIND(CHAR(1),SUBSTITUTE(_xlpm.t,"M",CHAR(1),_xlpm.k)),_xlpm.b,TRIM(LEFT(_xlpm.t,_xlpm.pos-1)),_xlpm.tok,TRIM(RIGHT(SUBSTITUTE(_xlpm.b," ",REPT(" ",30)),30)),_xlpm.z,_xlfn.SEQUENCE(LEN(_xlpm.tok)),_xlpm.q,MAX(IF(ISNUMBER(FIND(MID(_xlpm.tok,_xlpm.z,1),"0123456789.")),0,_xlpm.z)),_xlpm.num,MID(_xlpm.tok,_xlpm.q+1,30),VALUE(IF(LEFT(_xlpm.num,1)=".",MID(_xlpm.num,2,30),_xlpm.num))),""))} | G7: =IF(B7="","",IF(M7,"⚠ Duplicate (not counted)",IF(AND(I7="",D7="",E7=""),"— ignored",IF(C7="","⚠ Time",IF(D7="","⚠ Plant",IF(E7="","⚠ Quantity",IF(AND(ISNUMBER(L7),COUNTIF(L$1:L6,L7)>0),"⚠ Same serial "&L7,IF(AND(ISNUMBER(L7),L7>MIN($L$2:$L$1001),COUNTIF($L$2:$L$1001,L7-1)=0,COUNTIF($L$2:$L$1001,L7-2)<2),"⚠ Missing serial "&(L7-1),IF(AND(MAX(K$1:K6)>0,N(K7)-MAX(K$1:K6)>180),"⚠ Gap > 3h",IF(C7-I7>=0.99,"next day",IF(C7-I7>0.4,"12h → 24h",""))))))))))) | H7: =IF(B7="","",_xlfn.LET(_xlpm.t,TRIM(B7),IF(LEFT(_xlpm.t,1)="[",IFERROR(TRIM(MID(_xlpm.t,FIND(": ",_xlpm.t,FIND("]",_xlpm.t))+2,500)),_xlpm.t),_xlpm.t))) | I7: =IF(H7="","",IFERROR(TIMEVALUE(TRIM(SUBSTITUTE(SUBSTITUTE(MID(H7,SEARCH(":",H7)-2,5),".",""),"*",""))),"")) | J7: =IF(OR(B7="",F7="",M7),0,IF(ISNUMBER(F7),F7,N(E7))) -> 0 | K7: =IF(OR(C7="",M7),"",ROUND(C7*1440,0)) | L7: =IF(OR(H7="",AND(I7="",D7="")),"",IFERROR(_xlfn.LET(_xlpm.t,TRIM(SUBSTITUTE(SUBSTITUTE(H7,"*",""),"_","")),VALUE(SUBSTITUTE(LEFT(_xlpm.t,FIND(" ",_xlpm.t&" ")-1),".",""))),"")) | M7: {=IF(H7="",FALSE,SUMPRODUCT(--(H$1:H6=H7))>0)} -> FALSE
A8: =IF(OR(B8="",M8,G8="— ignored"),"",MAX(A$1:A7)+1) | C8: =IF(I8="","",ROUND((I8+0.5*MAX(0,CEILING(ROUND((MAX(C$1:C7)-1/48-I8)/0.5,6),1)))*1440,0)/1440) | D8: {=IF(H8="","",IFERROR(INDEX(Log!$C$19:$G$19,VALUE(MID(H8,FIND("#",H8)+1,1))),""))} | E8: {=IF(OR(H8="",M8),"",IFERROR(_xlfn.LET(_xlpm.t,SUBSTITUTE(UPPER(H8),"م","M"),_xlpm.u,SUBSTITUTE(_xlpm.t," ",""),_xlpm.s,_xlfn.SEQUENCE(LEN(_xlpm.u)),_xlpm.p,MIN(IF((MID(_xlpm.u,_xlpm.s,1)="M")*ISNUMBER(-MID(_xlpm.u,_xlpm.s-1,1)),_xlpm.s)),_xlpm.k,LEN(LEFT(_xlpm.u,_xlpm.p))-LEN(SUBSTITUTE(LEFT(_xlpm.u,_xlpm.p),"M","")),_xlpm.pos,FIND(CHAR(1),SUBSTITUTE(_xlpm.t,"M",CHAR(1),_xlpm.k)),_xlpm.b,TRIM(LEFT(_xlpm.t,_xlpm.pos-1)),_xlpm.tok,TRIM(RIGHT(SUBSTITUTE(_xlpm.b," ",REPT(" ",30)),30)),_xlpm.z,_xlfn.SEQUENCE(LEN(_xlpm.tok)),_xlpm.q,MAX(IF(ISNUMBER(FIND(MID(_xlpm.tok,_xlpm.z,1),"0123456789.")),0,_xlpm.z)),_xlpm.num,MID(_xlpm.tok,_xlpm.q+1,30),VALUE(IF(LEFT(_xlpm.num,1)=".",MID(_xlpm.num,2,30),_xlpm.num))),""))} | G8: =IF(B8="","",IF(M8,"⚠ Duplicate (not counted)",IF(AND(I8="",D8="",E8=""),"— ignored",IF(C8="","⚠ Time",IF(D8="","⚠ Plant",IF(E8="","⚠ Quantity",IF(AND(ISNUMBER(L8),COUNTIF(L$1:L7,L8)>0),"⚠ Same serial "&L8,IF(AND(ISNUMBER(L8),L8>MIN($L$2:$L$1001),COUNTIF($L$2:$L$1001,L8-1)=0,COUNTIF($L$2:$L$1001,L8-2)<2),"⚠ Missing serial "&(L8-1),IF(AND(MAX(K$1:K7)>0,N(K8)-MAX(K$1:K7)>180),"⚠ Gap > 3h",IF(C8-I8>=0.99,"next day",IF(C8-I8>0.4,"12h → 24h",""))))))))))) | H8: =IF(B8="","",_xlfn.LET(_xlpm.t,TRIM(B8),IF(LEFT(_xlpm.t,1)="[",IFERROR(TRIM(MID(_xlpm.t,FIND(": ",_xlpm.t,FIND("]",_xlpm.t))+2,500)),_xlpm.t),_xlpm.t))) | I8: =IF(H8="","",IFERROR(TIMEVALUE(TRIM(SUBSTITUTE(SUBSTITUTE(MID(H8,SEARCH(":",H8)-2,5),".",""),"*",""))),"")) | J8: =IF(OR(B8="",F8="",M8),0,IF(ISNUMBER(F8),F8,N(E8))) -> 0 | K8: =IF(OR(C8="",M8),"",ROUND(C8*1440,0)) | L8: =IF(OR(H8="",AND(I8="",D8="")),"",IFERROR(_xlfn.LET(_xlpm.t,TRIM(SUBSTITUTE(SUBSTITUTE(H8,"*",""),"_","")),VALUE(SUBSTITUTE(LEFT(_xlpm.t,FIND(" ",_xlpm.t&" ")-1),".",""))),"")) | M8: {=IF(H8="",FALSE,SUMPRODUCT(--(H$1:H7=H8))>0)} -> FALSE
A9: =IF(OR(B9="",M9,G9="— ignored"),"",MAX(A$1:A8)+1) | C9: =IF(I9="","",ROUND((I9+0.5*MAX(0,CEILING(ROUND((MAX(C$1:C8)-1/48-I9)/0.5,6),1)))*1440,0)/1440) | D9: {=IF(H9="","",IFERROR(INDEX(Log!$C$19:$G$19,VALUE(MID(H9,FIND("#",H9)+1,1))),""))} | E9: {=IF(OR(H9="",M9),"",IFERROR(_xlfn.LET(_xlpm.t,SUBSTITUTE(UPPER(H9),"م","M"),_xlpm.u,SUBSTITUTE(_xlpm.t," ",""),_xlpm.s,_xlfn.SEQUENCE(LEN(_xlpm.u)),_xlpm.p,MIN(IF((MID(_xlpm.u,_xlpm.s,1)="M")*ISNUMBER(-MID(_xlpm.u,_xlpm.s-1,1)),_xlpm.s)),_xlpm.k,LEN(LEFT(_xlpm.u,_xlpm.p))-LEN(SUBSTITUTE(LEFT(_xlpm.u,_xlpm.p),"M","")),_xlpm.pos,FIND(CHAR(1),SUBSTITUTE(_xlpm.t,"M",CHAR(1),_xlpm.k)),_xlpm.b,TRIM(LEFT(_xlpm.t,_xlpm.pos-1)),_xlpm.tok,TRIM(RIGHT(SUBSTITUTE(_xlpm.b," ",REPT(" ",30)),30)),_xlpm.z,_xlfn.SEQUENCE(LEN(_xlpm.tok)),_xlpm.q,MAX(IF(ISNUMBER(FIND(MID(_xlpm.tok,_xlpm.z,1),"0123456789.")),0,_xlpm.z)),_xlpm.num,MID(_xlpm.tok,_xlpm.q+1,30),VALUE(IF(LEFT(_xlpm.num,1)=".",MID(_xlpm.num,2,30),_xlpm.num))),""))} | G9: =IF(B9="","",IF(M9,"⚠ Duplicate (not counted)",IF(AND(I9="",D9="",E9=""),"— ignored",IF(C9="","⚠ Time",IF(D9="","⚠ Plant",IF(E9="","⚠ Quantity",IF(AND(ISNUMBER(L9),COUNTIF(L$1:L8,L9)>0),"⚠ Same serial "&L9,IF(AND(ISNUMBER(L9),L9>MIN($L$2:$L$1001),COUNTIF($L$2:$L$1001,L9-1)=0,COUNTIF($L$2:$L$1001,L9-2)<2),"⚠ Missing serial "&(L9-1),IF(AND(MAX(K$1:K8)>0,N(K9)-MAX(K$1:K8)>180),"⚠ Gap > 3h",IF(C9-I9>=0.99,"next day",IF(C9-I9>0.4,"12h → 24h",""))))))))))) | H9: =IF(B9="","",_xlfn.LET(_xlpm.t,TRIM(B9),IF(LEFT(_xlpm.t,1)="[",IFERROR(TRIM(MID(_xlpm.t,FIND(": ",_xlpm.t,FIND("]",_xlpm.t))+2,500)),_xlpm.t),_xlpm.t))) | I9: =IF(H9="","",IFERROR(TIMEVALUE(TRIM(SUBSTITUTE(SUBSTITUTE(MID(H9,SEARCH(":",H9)-2,5),".",""),"*",""))),"")) | J9: =IF(OR(B9="",F9="",M9),0,IF(ISNUMBER(F9),F9,N(E9))) -> 0 | K9: =IF(OR(C9="",M9),"",ROUND(C9*1440,0)) | L9: =IF(OR(H9="",AND(I9="",D9="")),"",IFERROR(_xlfn.LET(_xlpm.t,TRIM(SUBSTITUTE(SUBSTITUTE(H9,"*",""),"_","")),VALUE(SUBSTITUTE(LEFT(_xlpm.t,FIND(" ",_xlpm.t&" ")-1),".",""))),"")) | M9: {=IF(H9="",FALSE,SUMPRODUCT(--(H$1:H8=H9))>0)} -> FALSE
A10: =IF(OR(B10="",M10,G10="— ignored"),"",MAX(A$1:A9)+1) | C10: =IF(I10="","",ROUND((I10+0.5*MAX(0,CEILING(ROUND((MAX(C$1:C9)-1/48-I10)/0.5,6),1)))*1440,0)/1440) | D10: {=IF(H10="","",IFERROR(INDEX(Log!$C$19:$G$19,VALUE(MID(H10,FIND("#",H10)+1,1))),""))} | E10: {=IF(OR(H10="",M10),"",IFERROR(_xlfn.LET(_xlpm.t,SUBSTITUTE(UPPER(H10),"م","M"),_xlpm.u,SUBSTITUTE(_xlpm.t," ",""),_xlpm.s,_xlfn.SEQUENCE(LEN(_xlpm.u)),_xlpm.p,MIN(IF((MID(_xlpm.u,_xlpm.s,1)="M")*ISNUMBER(-MID(_xlpm.u,_xlpm.s-1,1)),_xlpm.s)),_xlpm.k,LEN(LEFT(_xlpm.u,_xlpm.p))-LEN(SUBSTITUTE(LEFT(_xlpm.u,_xlpm.p),"M","")),_xlpm.pos,FIND(CHAR(1),SUBSTITUTE(_xlpm.t,"M",CHAR(1),_xlpm.k)),_xlpm.b,TRIM(LEFT(_xlpm.t,_xlpm.pos-1)),_xlpm.tok,TRIM(RIGHT(SUBSTITUTE(_xlpm.b," ",REPT(" ",30)),30)),_xlpm.z,_xlfn.SEQUENCE(LEN(_xlpm.tok)),_xlpm.q,MAX(IF(ISNUMBER(FIND(MID(_xlpm.tok,_xlpm.z,1),"0123456789.")),0,_xlpm.z)),_xlpm.num,MID(_xlpm.tok,_xlpm.q+1,30),VALUE(IF(LEFT(_xlpm.num,1)=".",MID(_xlpm.num,2,30),_xlpm.num))),""))} | G10: =IF(B10="","",IF(M10,"⚠ Duplicate (not counted)",IF(AND(I10="",D10="",E10=""),"— ignored",IF(C10="","⚠ Time",IF(D10="","⚠ Plant",IF(E10="","⚠ Quantity",IF(AND(ISNUMBER(L10),COUNTIF(L$1:L9,L10)>0),"⚠ Same serial "&L10,IF(AND(ISNUMBER(L10),L10>MIN($L$2:$L$1001),COUNTIF($L$2:$L$1001,L10-1)=0,COUNTIF($L$2:$L$1001,L10-2)<2),"⚠ Missing serial "&(L10-1),IF(AND(MAX(K$1:K9)>0,N(K10)-MAX(K$1:K9)>180),"⚠ Gap > 3h",IF(C10-I10>=0.99,"next day",IF(C10-I10>0.4,"12h → 24h",""))))))))))) | H10: =IF(B10="","",_xlfn.LET(_xlpm.t,TRIM(B10),IF(LEFT(_xlpm.t,1)="[",IFERROR(TRIM(MID(_xlpm.t,FIND(": ",_xlpm.t,FIND("]",_xlpm.t))+2,500)),_xlpm.t),_xlpm.t))) | I10: =IF(H10="","",IFERROR(TIMEVALUE(TRIM(SUBSTITUTE(SUBSTITUTE(MID(H10,SEARCH(":",H10)-2,5),".",""),"*",""))),"")) | J10: =IF(OR(B10="",F10="",M10),0,IF(ISNUMBER(F10),F10,N(E10))) -> 0 | K10: =IF(OR(C10="",M10),"",ROUND(C10*1440,0)) | L10: =IF(OR(H10="",AND(I10="",D10="")),"",IFERROR(_xlfn.LET(_xlpm.t,TRIM(SUBSTITUTE(SUBSTITUTE(H10,"*",""),"_","")),VALUE(SUBSTITUTE(LEFT(_xlpm.t,FIND(" ",_xlpm.t&" ")-1),".",""))),"")) | M10: {=IF(H10="",FALSE,SUMPRODUCT(--(H$1:H9=H10))>0)} -> FALSE
A11: =IF(OR(B11="",M11,G11="— ignored"),"",MAX(A$1:A10)+1) | C11: =IF(I11="","",ROUND((I11+0.5*MAX(0,CEILING(ROUND((MAX(C$1:C10)-1/48-I11)/0.5,6),1)))*1440,0)/1440) | D11: {=IF(H11="","",IFERROR(INDEX(Log!$C$19:$G$19,VALUE(MID(H11,FIND("#",H11)+1,1))),""))} | E11: {=IF(OR(H11="",M11),"",IFERROR(_xlfn.LET(_xlpm.t,SUBSTITUTE(UPPER(H11),"م","M"),_xlpm.u,SUBSTITUTE(_xlpm.t," ",""),_xlpm.s,_xlfn.SEQUENCE(LEN(_xlpm.u)),_xlpm.p,MIN(IF((MID(_xlpm.u,_xlpm.s,1)="M")*ISNUMBER(-MID(_xlpm.u,_xlpm.s-1,1)),_xlpm.s)),_xlpm.k,LEN(LEFT(_xlpm.u,_xlpm.p))-LEN(SUBSTITUTE(LEFT(_xlpm.u,_xlpm.p),"M","")),_xlpm.pos,FIND(CHAR(1),SUBSTITUTE(_xlpm.t,"M",CHAR(1),_xlpm.k)),_xlpm.b,TRIM(LEFT(_xlpm.t,_xlpm.pos-1)),_xlpm.tok,TRIM(RIGHT(SUBSTITUTE(_xlpm.b," ",REPT(" ",30)),30)),_xlpm.z,_xlfn.SEQUENCE(LEN(_xlpm.tok)),_xlpm.q,MAX(IF(ISNUMBER(FIND(MID(_xlpm.tok,_xlpm.z,1),"0123456789.")),0,_xlpm.z)),_xlpm.num,MID(_xlpm.tok,_xlpm.q+1,30),VALUE(IF(LEFT(_xlpm.num,1)=".",MID(_xlpm.num,2,30),_xlpm.num))),""))} | G11: =IF(B11="","",IF(M11,"⚠ Duplicate (not counted)",IF(AND(I11="",D11="",E11=""),"— ignored",IF(C11="","⚠ Time",IF(D11="","⚠ Plant",IF(E11="","⚠ Quantity",IF(AND(ISNUMBER(L11),COUNTIF(L$1:L10,L11)>0),"⚠ Same serial "&L11,IF(AND(ISNUMBER(L11),L11>MIN($L$2:$L$1001),COUNTIF($L$2:$L$1001,L11-1)=0,COUNTIF($L$2:$L$1001,L11-2)<2),"⚠ Missing serial "&(L11-1),IF(AND(MAX(K$1:K10)>0,N(K11)-MAX(K$1:K10)>180),"⚠ Gap > 3h",IF(C11-I11>=0.99,"next day",IF(C11-I11>0.4,"12h → 24h",""))))))))))) | H11: =IF(B11="","",_xlfn.LET(_xlpm.t,TRIM(B11),IF(LEFT(_xlpm.t,1)="[",IFERROR(TRIM(MID(_xlpm.t,FIND(": ",_xlpm.t,FIND("]",_xlpm.t))+2,500)),_xlpm.t),_xlpm.t))) | I11: =IF(H11="","",IFERROR(TIMEVALUE(TRIM(SUBSTITUTE(SUBSTITUTE(MID(H11,SEARCH(":",H11)-2,5),".",""),"*",""))),"")) | J11: =IF(OR(B11="",F11="",M11),0,IF(ISNUMBER(F11),F11,N(E11))) -> 0 | K11: =IF(OR(C11="",M11),"",ROUND(C11*1440,0)) | L11: =IF(OR(H11="",AND(I11="",D11="")),"",IFERROR(_xlfn.LET(_xlpm.t,TRIM(SUBSTITUTE(SUBSTITUTE(H11,"*",""),"_","")),VALUE(SUBSTITUTE(LEFT(_xlpm.t,FIND(" ",_xlpm.t&" ")-1),".",""))),"")) | M11: {=IF(H11="",FALSE,SUMPRODUCT(--(H$1:H10=H11))>0)} -> FALSE
A12: =IF(OR(B12="",M12,G12="— ignored"),"",MAX(A$1:A11)+1) | C12: =IF(I12="","",ROUND((I12+0.5*MAX(0,CEILING(ROUND((MAX(C$1:C11)-1/48-I12)/0.5,6),1)))*1440,0)/1440) | D12: {=IF(H12="","",IFERROR(INDEX(Log!$C$19:$G$19,VALUE(MID(H12,FIND("#",H12)+1,1))),""))} | E12: {=IF(OR(H12="",M12),"",IFERROR(_xlfn.LET(_xlpm.t,SUBSTITUTE(UPPER(H12),"م","M"),_xlpm.u,SUBSTITUTE(_xlpm.t," ",""),_xlpm.s,_xlfn.SEQUENCE(LEN(_xlpm.u)),_xlpm.p,MIN(IF((MID(_xlpm.u,_xlpm.s,1)="M")*ISNUMBER(-MID(_xlpm.u,_xlpm.s-1,1)),_xlpm.s)),_xlpm.k,LEN(LEFT(_xlpm.u,_xlpm.p))-LEN(SUBSTITUTE(LEFT(_xlpm.u,_xlpm.p),"M","")),_xlpm.pos,FIND(CHAR(1),SUBSTITUTE(_xlpm.t,"M",CHAR(1),_xlpm.k)),_xlpm.b,TRIM(LEFT(_xlpm.t,_xlpm.pos-1)),_xlpm.tok,TRIM(RIGHT(SUBSTITUTE(_xlpm.b," ",REPT(" ",30)),30)),_xlpm.z,_xlfn.SEQUENCE(LEN(_xlpm.tok)),_xlpm.q,MAX(IF(ISNUMBER(FIND(MID(_xlpm.tok,_xlpm.z,1),"0123456789.")),0,_xlpm.z)),_xlpm.num,MID(_xlpm.tok,_xlpm.q+1,30),VALUE(IF(LEFT(_xlpm.num,1)=".",MID(_xlpm.num,2,30),_xlpm.num))),""))} | G12: =IF(B12="","",IF(M12,"⚠ Duplicate (not counted)",IF(AND(I12="",D12="",E12=""),"— ignored",IF(C12="","⚠ Time",IF(D12="","⚠ Plant",IF(E12="","⚠ Quantity",IF(AND(ISNUMBER(L12),COUNTIF(L$1:L11,L12)>0),"⚠ Same serial "&L12,IF(AND(ISNUMBER(L12),L12>MIN($L$2:$L$1001),COUNTIF($L$2:$L$1001,L12-1)=0,COUNTIF($L$2:$L$1001,L12-2)<2),"⚠ Missing serial "&(L12-1),IF(AND(MAX(K$1:K11)>0,N(K12)-MAX(K$1:K11)>180),"⚠ Gap > 3h",IF(C12-I12>=0.99,"next day",IF(C12-I12>0.4,"12h → 24h",""))))))))))) | H12: =IF(B12="","",_xlfn.LET(_xlpm.t,TRIM(B12),IF(LEFT(_xlpm.t,1)="[",IFERROR(TRIM(MID(_xlpm.t,FIND(": ",_xlpm.t,FIND("]",_xlpm.t))+2,500)),_xlpm.t),_xlpm.t))) | I12: =IF(H12="","",IFERROR(TIMEVALUE(TRIM(SUBSTITUTE(SUBSTITUTE(MID(H12,SEARCH(":",H12)-2,5),".",""),"*",""))),"")) | J12: =IF(OR(B12="",F12="",M12),0,IF(ISNUMBER(F12),F12,N(E12))) -> 0 | K12: =IF(OR(C12="",M12),"",ROUND(C12*1440,0)) | L12: =IF(OR(H12="",AND(I12="",D12="")),"",IFERROR(_xlfn.LET(_xlpm.t,TRIM(SUBSTITUTE(SUBSTITUTE(H12,"*",""),"_","")),VALUE(SUBSTITUTE(LEFT(_xlpm.t,FIND(" ",_xlpm.t&" ")-1),".",""))),"")) | M12: {=IF(H12="",FALSE,SUMPRODUCT(--(H$1:H11=H12))>0)} -> FALSE
A13: =IF(OR(B13="",M13,G13="— ignored"),"",MAX(A$1:A12)+1) | C13: =IF(I13="","",ROUND((I13+0.5*MAX(0,CEILING(ROUND((MAX(C$1:C12)-1/48-I13)/0.5,6),1)))*1440,0)/1440) | D13: {=IF(H13="","",IFERROR(INDEX(Log!$C$19:$G$19,VALUE(MID(H13,FIND("#",H13)+1,1))),""))} | E13: {=IF(OR(H13="",M13),"",IFERROR(_xlfn.LET(_xlpm.t,SUBSTITUTE(UPPER(H13),"م","M"),_xlpm.u,SUBSTITUTE(_xlpm.t," ",""),_xlpm.s,_xlfn.SEQUENCE(LEN(_xlpm.u)),_xlpm.p,MIN(IF((MID(_xlpm.u,_xlpm.s,1)="M")*ISNUMBER(-MID(_xlpm.u,_xlpm.s-1,1)),_xlpm.s)),_xlpm.k,LEN(LEFT(_xlpm.u,_xlpm.p))-LEN(SUBSTITUTE(LEFT(_xlpm.u,_xlpm.p),"M","")),_xlpm.pos,FIND(CHAR(1),SUBSTITUTE(_xlpm.t,"M",CHAR(1),_xlpm.k)),_xlpm.b,TRIM(LEFT(_xlpm.t,_xlpm.pos-1)),_xlpm.tok,TRIM(RIGHT(SUBSTITUTE(_xlpm.b," ",REPT(" ",30)),30)),_xlpm.z,_xlfn.SEQUENCE(LEN(_xlpm.tok)),_xlpm.q,MAX(IF(ISNUMBER(FIND(MID(_xlpm.tok,_xlpm.z,1),"0123456789.")),0,_xlpm.z)),_xlpm.num,MID(_xlpm.tok,_xlpm.q+1,30),VALUE(IF(LEFT(_xlpm.num,1)=".",MID(_xlpm.num,2,30),_xlpm.num))),""))} | G13: =IF(B13="","",IF(M13,"⚠ Duplicate (not counted)",IF(AND(I13="",D13="",E13=""),"— ignored",IF(C13="","⚠ Time",IF(D13="","⚠ Plant",IF(E13="","⚠ Quantity",IF(AND(ISNUMBER(L13),COUNTIF(L$1:L12,L13)>0),"⚠ Same serial "&L13,IF(AND(ISNUMBER(L13),L13>MIN($L$2:$L$1001),COUNTIF($L$2:$L$1001,L13-1)=0,COUNTIF($L$2:$L$1001,L13-2)<2),"⚠ Missing serial "&(L13-1),IF(AND(MAX(K$1:K12)>0,N(K13)-MAX(K$1:K12)>180),"⚠ Gap > 3h",IF(C13-I13>=0.99,"next day",IF(C13-I13>0.4,"12h → 24h",""))))))))))) | H13: =IF(B13="","",_xlfn.LET(_xlpm.t,TRIM(B13),IF(LEFT(_xlpm.t,1)="[",IFERROR(TRIM(MID(_xlpm.t,FIND(": ",_xlpm.t,FIND("]",_xlpm.t))+2,500)),_xlpm.t),_xlpm.t))) | I13: =IF(H13="","",IFERROR(TIMEVALUE(TRIM(SUBSTITUTE(SUBSTITUTE(MID(H13,SEARCH(":",H13)-2,5),".",""),"*",""))),"")) | J13: =IF(OR(B13="",F13="",M13),0,IF(ISNUMBER(F13),F13,N(E13))) -> 0 | K13: =IF(OR(C13="",M13),"",ROUND(C13*1440,0)) | L13: =IF(OR(H13="",AND(I13="",D13="")),"",IFERROR(_xlfn.LET(_xlpm.t,TRIM(SUBSTITUTE(SUBSTITUTE(H13,"*",""),"_","")),VALUE(SUBSTITUTE(LEFT(_xlpm.t,FIND(" ",_xlpm.t&" ")-1),".",""))),"")) | M13: {=IF(H13="",FALSE,SUMPRODUCT(--(H$1:H12=H13))>0)} -> FALSE
A14: =IF(OR(B14="",M14,G14="— ignored"),"",MAX(A$1:A13)+1) | C14: =IF(I14="","",ROUND((I14+0.5*MAX(0,CEILING(ROUND((MAX(C$1:C13)-1/48-I14)/0.5,6),1)))*1440,0)/1440) | D14: {=IF(H14="","",IFERROR(INDEX(Log!$C$19:$G$19,VALUE(MID(H14,FIND("#",H14)+1,1))),""))} | E14: {=IF(OR(H14="",M14),"",IFERROR(_xlfn.LET(_xlpm.t,SUBSTITUTE(UPPER(H14),"م","M"),_xlpm.u,SUBSTITUTE(_xlpm.t," ",""),_xlpm.s,_xlfn.SEQUENCE(LEN(_xlpm.u)),_xlpm.p,MIN(IF((MID(_xlpm.u,_xlpm.s,1)="M")*ISNUMBER(-MID(_xlpm.u,_xlpm.s-1,1)),_xlpm.s)),_xlpm.k,LEN(LEFT(_xlpm.u,_xlpm.p))-LEN(SUBSTITUTE(LEFT(_xlpm.u,_xlpm.p),"M","")),_xlpm.pos,FIND(CHAR(1),SUBSTITUTE(_xlpm.t,"M",CHAR(1),_xlpm.k)),_xlpm.b,TRIM(LEFT(_xlpm.t,_xlpm.pos-1)),_xlpm.tok,TRIM(RIGHT(SUBSTITUTE(_xlpm.b," ",REPT(" ",30)),30)),_xlpm.z,_xlfn.SEQUENCE(LEN(_xlpm.tok)),_xlpm.q,MAX(IF(ISNUMBER(FIND(MID(_xlpm.tok,_xlpm.z,1),"0123456789.")),0,_xlpm.z)),_xlpm.num,MID(_xlpm.tok,_xlpm.q+1,30),VALUE(IF(LEFT(_xlpm.num,1)=".",MID(_xlpm.num,2,30),_xlpm.num))),""))} | G14: =IF(B14="","",IF(M14,"⚠ Duplicate (not counted)",IF(AND(I14="",D14="",E14=""),"— ignored",IF(C14="","⚠ Time",IF(D14="","⚠ Plant",IF(E14="","⚠ Quantity",IF(AND(ISNUMBER(L14),COUNTIF(L$1:L13,L14)>0),"⚠ Same serial "&L14,IF(AND(ISNUMBER(L14),L14>MIN($L$2:$L$1001),COUNTIF($L$2:$L$1001,L14-1)=0,COUNTIF($L$2:$L$1001,L14-2)<2),"⚠ Missing serial "&(L14-1),IF(AND(MAX(K$1:K13)>0,N(K14)-MAX(K$1:K13)>180),"⚠ Gap > 3h",IF(C14-I14>=0.99,"next day",IF(C14-I14>0.4,"12h → 24h",""))))))))))) | H14: =IF(B14="","",_xlfn.LET(_xlpm.t,TRIM(B14),IF(LEFT(_xlpm.t,1)="[",IFERROR(TRIM(MID(_xlpm.t,FIND(": ",_xlpm.t,FIND("]",_xlpm.t))+2,500)),_xlpm.t),_xlpm.t))) | I14: =IF(H14="","",IFERROR(TIMEVALUE(TRIM(SUBSTITUTE(SUBSTITUTE(MID(H14,SEARCH(":",H14)-2,5),".",""),"*",""))),"")) | J14: =IF(OR(B14="",F14="",M14),0,IF(ISNUMBER(F14),F14,N(E14))) -> 0 | K14: =IF(OR(C14="",M14),"",ROUND(C14*1440,0)) | L14: =IF(OR(H14="",AND(I14="",D14="")),"",IFERROR(_xlfn.LET(_xlpm.t,TRIM(SUBSTITUTE(SUBSTITUTE(H14,"*",""),"_","")),VALUE(SUBSTITUTE(LEFT(_xlpm.t,FIND(" ",_xlpm.t&" ")-1),".",""))),"")) | M14: {=IF(H14="",FALSE,SUMPRODUCT(--(H$1:H13=H14))>0)} -> FALSE
A15: =IF(OR(B15="",M15,G15="— ignored"),"",MAX(A$1:A14)+1) | C15: =IF(I15="","",ROUND((I15+0.5*MAX(0,CEILING(ROUND((MAX(C$1:C14)-1/48-I15)/0.5,6),1)))*1440,0)/1440) | D15: {=IF(H15="","",IFERROR(INDEX(Log!$C$19:$G$19,VALUE(MID(H15,FIND("#",H15)+1,1))),""))} | E15: {=IF(OR(H15="",M15),"",IFERROR(_xlfn.LET(_xlpm.t,SUBSTITUTE(UPPER(H15),"م","M"),_xlpm.u,SUBSTITUTE(_xlpm.t," ",""),_xlpm.s,_xlfn.SEQUENCE(LEN(_xlpm.u)),_xlpm.p,MIN(IF((MID(_xlpm.u,_xlpm.s,1)="M")*ISNUMBER(-MID(_xlpm.u,_xlpm.s-1,1)),_xlpm.s)),_xlpm.k,LEN(LEFT(_xlpm.u,_xlpm.p))-LEN(SUBSTITUTE(LEFT(_xlpm.u,_xlpm.p),"M","")),_xlpm.pos,FIND(CHAR(1),SUBSTITUTE(_xlpm.t,"M",CHAR(1),_xlpm.k)),_xlpm.b,TRIM(LEFT(_xlpm.t,_xlpm.pos-1)),_xlpm.tok,TRIM(RIGHT(SUBSTITUTE(_xlpm.b," ",REPT(" ",30)),30)),_xlpm.z,_xlfn.SEQUENCE(LEN(_xlpm.tok)),_xlpm.q,MAX(IF(ISNUMBER(FIND(MID(_xlpm.tok,_xlpm.z,1),"0123456789.")),0,_xlpm.z)),_xlpm.num,MID(_xlpm.tok,_xlpm.q+1,30),VALUE(IF(LEFT(_xlpm.num,1)=".",MID(_xlpm.num,2,30),_xlpm.num))),""))} | G15: =IF(B15="","",IF(M15,"⚠ Duplicate (not counted)",IF(AND(I15="",D15="",E15=""),"— ignored",IF(C15="","⚠ Time",IF(D15="","⚠ Plant",IF(E15="","⚠ Quantity",IF(AND(ISNUMBER(L15),COUNTIF(L$1:L14,L15)>0),"⚠ Same serial "&L15,IF(AND(ISNUMBER(L15),L15>MIN($L$2:$L$1001),COUNTIF($L$2:$L$1001,L15-1)=0,COUNTIF($L$2:$L$1001,L15-2)<2),"⚠ Missing serial "&(L15-1),IF(AND(MAX(K$1:K14)>0,N(K15)-MAX(K$1:K14)>180),"⚠ Gap > 3h",IF(C15-I15>=0.99,"next day",IF(C15-I15>0.4,"12h → 24h",""))))))))))) | H15: =IF(B15="","",_xlfn.LET(_xlpm.t,TRIM(B15),IF(LEFT(_xlpm.t,1)="[",IFERROR(TRIM(MID(_xlpm.t,FIND(": ",_xlpm.t,FIND("]",_xlpm.t))+2,500)),_xlpm.t),_xlpm.t))) | I15: =IF(H15="","",IFERROR(TIMEVALUE(TRIM(SUBSTITUTE(SUBSTITUTE(MID(H15,SEARCH(":",H15)-2,5),".",""),"*",""))),"")) | J15: =IF(OR(B15="",F15="",M15),0,IF(ISNUMBER(F15),F15,N(E15))) -> 0 | K15: =IF(OR(C15="",M15),"",ROUND(C15*1440,0)) | L15: =IF(OR(H15="",AND(I15="",D15="")),"",IFERROR(_xlfn.LET(_xlpm.t,TRIM(SUBSTITUTE(SUBSTITUTE(H15,"*",""),"_","")),VALUE(SUBSTITUTE(LEFT(_xlpm.t,FIND(" ",_xlpm.t&" ")-1),".",""))),"")) | M15: {=IF(H15="",FALSE,SUMPRODUCT(--(H$1:H14=H15))>0)} -> FALSE
